Workbook
Name Блокуправления: Прайсы!$BC$3:$BC$7
Name Выкл: Прайсы!$CB$3:$CB$50
Name Доп: Прайсы!$CH$3:$CH$106
Name МПЗ: Прайсы!$AW$3:$AW$108
Name НомерСхемы: #REF!
Name ОПН: Прайсы!$AQ$3:$AQ$19
Name ПТ: Прайсы!$DF$3:$DF$4
Name Разъединитель: Прайсы!$L$3:$L$20
Name Счетчик10: Прайсы!$CX$3:$CX$75
Name ТН: Прайсы!$AG$3:$AG$21
Name Трансформатортока: Прайсы!$B$3:$B$122
Name ТСН: Прайсы!$BH$3:$BH$15
Name ТТнулевойпоследлвательности: Прайсы!$W$3:$W$18

Sheet КСО-204
B1: =" Опросный лист на "& IF(C7>0, C7,"КСО-204, КСО-204м") -> Опросный лист на КСО-204 | H1: №
B2: Заказчик / Название объекта: | K2: дата
D4: название организации
D6: должность | F6: ФИО | I6: подпись | K6: тел. / факс
A7: 1 | B7: Тип камеры КСО | C7: КСО-204
A8: Запрашиваемые данные | D8: Ответы заказчика
A9: 2 | B9: Номер камеры по плану
A10: 3 | B10: Номер схемы главных цепей
A11: 4 | B11: Номинальное напряжение, кВ | C11: 10
A12: 5 | B12: Номинальный ток сборных шин, А | C12: 630
A13: 6 | B13: Ток к.з. на сборных шинах, кА
A14: 7 | B14: Схемы первичных соединений (однолинейная схема) выбирются автоматически
A15: 8 | B15: Назначение камер
A16: 9 | B16: Номер схемы вспомогательных цепей | D16: =IF(D15<>"",расчет!C29,"") -> 7ВВ | E16: =IF(E15<>"",расчет!E29,"") -> 7ВВ | F16: =IF(F15<>"",расчет!G29,"") -> 7ВВ | G16: =IF(G15<>"",расчет!I29,"") -> 15-400 | H16: =IF(H15<>"",расчет!K29,"") -> 13-400 | I16: =IF(I15<>"",расчет!M29,"") -> 3ВВ | J16: =IF(J15<>"",расчет!O29,"") -> 24-1000 | K16: =IF(K15<>"",расчет!Q29,"") | L16: =IF(L15<>"",расчет!S29,"") | M16: =IF(M15<>"",расчет!U29,"")
A17: 10 | B17: Шинный разъединитель
A18: 11 | B18: Выключатель | C18: тип
C19: БУ
A20: 12 | B20: Микропроцессорные реле | C20: тип
A21: 13 | B21: Трансформатор тока (ТПОЛ, ТОЛ) | C21: кол-во
C22: коэф. транс.
A23: 14 | B23: Линейный разъединитель
A24: 14 | B24: Cчетчик учёта ЭЭ, тип
A25: 14 | B25: Трансформатор напряжения
A26: 15 | B26: Трансформатор собственных нужд
A27: 16 | B27: Предохранитель, тип
A28: 17 | B28: ОПН (ОПН-РТ/TEL)
A29: 18 | B29: Элементы электромагнитной блокировки | C29: ВП-19
C30: ЗБ-1М
A31: 19 | B31: Трансформатор тока нулевой последовательности
A32: 20 | B32: Дополнительно | C32: кол-во
C33: оборудование
A34: 21 | B34: Дополнительно | C34: кол-во
C35: оборудование
A36: 22 | B36: Дополнительно | C36: кол-во
C37: оборудование
A38: 23 | B38: Дополнительно | C38: кол-во
C39: оборудование
A40: 24 | B40: Дополнительно | C40: кол-во
C41: оборудование
A42: 25 | B42: Дополнительно | C42: кол-во
...

Sheet Сводная информация
A1: Комплектация
A2: № | B2: Наименование оборудования | C2: Кол-во, шт | D2: Цена за ед. продукции без НДС, руб | E2: Стоимость без НДС, руб | F2: Комплектация без НДС | G2: Стоимость комплектации без НДС, руб | I2: расшифровка позиций 1/0 | J2: 1 | K2: 1СШ | L2: 2СШ
B3: =IF('КСО-204'!D15="","",расчет!C36) -> КСО-204 сх7ВВ-Линия, Шинный разъединитель: РВФЗ-10/1000, Вакуумный выключатель: VM12-10-20/1000, Блок управления: CVM 1.2 ВЕАШ468389.001-01, Микропроцессорная защита: АГАТ 200. А, Трансформаторы тока: 3хТПЛ-10 200/5 0,5S/10P, Линейный разъединитель: РВЗ-10/1000, Прибор учёта: Меркурий 234 АRTM(Х)2-00 (D)PBR.G, Трансформатор тока нулевой последовательности: ТЗЛМ-1 | C3: 0 | D3: =расчет!C35 -> 636183 | E3: =D3*C3 -> 2544732 | F3: =расчет!C34 -> 409844 | G3: =F3*C3 -> 1639376
B4: =IF('КСО-204'!E15="","",расчет!E36) -> КСО-204 сх7ВВ-Линия, Шинный разъединитель: РВФЗ-10/1000, Вакуумный выключатель: VM12-10-20/1000, Блок управления: CVM 1.2 ВЕАШ468389.001-01, Микропроцессорная защита: АГАТ 200. А, Трансформаторы тока: 3хТПЛ-10 600/5 0,5S/10P, Линейный разъединитель: РВЗ-10/1000, Прибор учёта: Меркурий 234 АRTM(Х)2-00 (D)PBR.G, Трансформатор тока нулевой последовательности: ТЗЛМ-1 | C4: 0 | D4: =расчет!E35 -> 636183 | E4: =D4*C4 -> 1272366 | F4: =расчет!E34 -> 409844 | G4: =F4*C4 -> 819688
B5: =IF('КСО-204'!F15="","",расчет!G36) -> КСО-204 сх7ВВ-Ввод, Шинный разъединитель: РВФЗ-10/1000, Вакуумный выключатель: VM12-10-20/1000, Блок управления: CVM 1.2 ВЕАШ468389.001-01, Микропроцессорная защита: АГАТ 200. АВ, Трансформаторы тока: 3хТПЛ-10 1000/5 0,5S/10P, Линейный разъединитель: РВЗ-10/1000, Прибор учёта: Меркурий 234 АRTM(Х)2-00 (D)PBR.G, Ограничитель перенапряжения: 3хОПН-П-6/7.2/10/550 | C5: 0 | D5: =расчет!G35 -> 645846 | E5: =D5*C5 -> 1291692 | F5: =расчет!G34 -> 418628 | G5: =F5*C5 -> 837256
B6: =IF('КСО-204'!G15="","",расчет!I36) -> КСО-204 сх15-400-ТСН, Шинный разъединитель: РВФЗ-10/1000, Трансформатор собственных нужд: ТЛС-25, 3хПатрон ПТ | C6: 0 | D6: =расчет!I35 -> 504607 | E6: =D6*C6 -> 1009214 | F6: =расчет!I34 -> 296723 | G6: =F6*C6 -> 593446
B7: =IF('КСО-204'!H15="","",расчет!K36) -> КСО-204 сх13-400-ТН, Шинный разъединитель: РВФЗ-10/1000, Микропроцессорная защита: АГАТ 200. В, Линейный разъединитель: ЗР-10, Трансформатор напряжения: НАМИТ-6, Ограничитель перенапряжения: 3хОПН-П-6/7.2/10/550 | C7: 0 | D7: =расчет!K35 -> 446484 | E7: =D7*C7 -> 892968 | F7: =расчет!K34 -> 262545 | G7: =F7*C7 -> 525090
B8: =IF('КСО-204'!I15="","",расчет!M36) -> КСО-204 сх3ВВ-СВ, Шинный разъединитель: РВФЗ-10/1000, Вакуумный выключатель: VM12-10-20/1000, Блок управления: CVM 1.2 ВЕАШ468389.001-01, Микропроцессорная защита: АГАТ 200. АВ, Трансформаторы тока: 3хТПЛ-10 800/5 0,5S/10P | C8: 0 | D8: =расчет!M35 -> 597437 | E8: =D8*C8 -> 597437 | F8: =расчет!M34 -> 374620 | G8: =F8*C8 -> 374620
B9: =IF('КСО-204'!J15="","",расчет!O36) -> КСО-204 сх24-1000-СР, Шинный разъединитель: РВФЗ-10/1000 | C9: 0 | D9: =расчет!O35 -> 135526 | E9: =D9*C9 -> 135526 | F9: =расчет!O34 -> 79693 | G9: =F9*C9 -> 79693
B10: =IF('КСО-204'!K15="","",расчет!Q36) | C10: 0 | D10: =расчет!Q35 -> 0 | E10: =D10*C10 -> 0 | F10: =расчет!Q34 -> 0 | G10: =F10*C10 -> 0
B11: =IF('КСО-204'!L15="","",расчет!S36) | C11: 0 | D11: =расчет!S35 -> 0 | E11: =D11*C11 -> 0 | F11: =расчет!S34 -> 0 | G11: =F11*C11 -> 0
B12: =IF('КСО-204'!M15="","",расчет!U36) | C12: 0 | D12: =расчет!U35 -> 0 | E12: =D12*C12 -> 0 | F12: =расчет!U34 -> 0 | G12: =F12*C12 -> 0
C13: =SUM(C3:C12) -> 14 | G13: =SUM(G3:G12) -> 4869169
C19: =IF(B19="",0,1) -> 0

Sheet Прайсы
A1: Трансформатортока | B1: без НДС | K1: Разъединитель | V1: ТТнулевойпоследлвательности | AF1: ТН | AP1: ОПН | AV1: МПЗ | BB1: Блокуправления | BG1: ТСН | BQ1: ТН | EX1: 211
A2: Код | B2: ТТ | C2: Цена | D2: Дата | E2: код1с | F2: код2с | G2: код3с | H2: код4с | I2: категория | K2: Код | L2: РВЗ | M2: Цена | N2: Дата | O2: Основание | P2: код1с | Q2: код2с | R2: код3с | S2: код4с | T2: категория | V2: Код | W2: ТТНП | X2: Поле1 | Y2: Дата | Z2: код1с | AA2: код2с | AB2: код3с | AC2: код4с | AD2: категория | AF2: Код | AG2: ТН | AH2: цена | AI2: Дата | AJ2: код1с | AK2: код2с | AL2: код3с | AM2: код4с | AN2: категория | AP2: Код | AQ2: ОПН | AR2: Цена | AS2: Дата | AT2: Основание | AV2: Код | AW2: МПЗ | AX2: Цена | AY2: Дата | AZ2: Основание | BB2: Код | BC2: БУ | BD2: цена | BE2: дата | BG2: Код | BH2: ТСН | BI2: Цена | BJ2: Дата | BK2: код1с | BL2: код2с | BM2: код3с | BN2: код4с | BO2: категория | BQ2: Код | BR2: ТН | BS2: цена | BT2: Дата | BU2: код1с | BV2: код2с | BW2: код3с | BX2: код4с | BY2: категория | CA2: Код | CB2: Выкл | CC2: цена | CD2: дата | CE2: место применения | CG2: Код | CH2: Доп | CI2: Цена | CJ2: Дата | CK2: Основание | CL2: код1с | CM2: код2с | CN2: код3с | CO2: код4с | CP2: категория | CR2: Код | CS2: Накладные | CT2: Цена | CU2: Дата | CW2: Код | CX2: счетчик | CY2: ном ток | CZ2: цена | DA2: дата | DC2: ШСН | DE2: Код | DF2: ПТ | DG2: Прайс код | DH2: Ном ток | DI2: цена | DJ2: дата | DL2: Код | DM2: КодСхема | DN2: ТИП | DO2: Схема | DP2: Назначение | DQ2: ШР | DR2: Вакуумник | DS2: БУ | DT2: МПЗ | DU2: колТТ | DV2: ТТ | DW2: ЛР | DX2: Счетчик | DY2: ТН | DZ2: ТСН | EA2: ПТ | EB2: ОПН | EC2: ТТНП | ED2: ШСН | EF2: Код | EG2: Имя | EH2: Цена | EI2: Дата | EK2: Ном. Ток | EL2: Сечение (Сu) | EM2: Вес 1 п/м, кг | EN2: Ном. Ток | EO2: Цена 1 п/м (фазы) | EQ2: Ном. Ток | ER2: Сечение (Al) | ES2: Вес 1 п/м, кг | ET2: Ном. Ток | EU2: Цена 1 п/м (фазы) | EW2: 630/1000 | EX2: 630/1000 | EY2: 1600
A3: 81 | B3: ТПЛ-10 50/5 0,2S/0,5S/10P | C3: 25800 | D3: 45614 | K3: 1 | L3: РВЗ-10/630 | M3: 17670 | N3: 45680 | O3: 1 | P3: ЭБ000003959 | Q3: ЭБ000003958 | T3: 3 | V3: 1 | W3: ТЗЛМ-1 | X3: 3450 | Y3: 45572 | Z3: Э0000001052 | AA3: м0000004378 | AB3: м0000004379 | AC3: Э0000000969 | AD3: 3 | AF3: 9 | AG3: 3хЗНОЛП-ЭК-10 М1ТА | AH3: 96400 | AI3: 44301 | AN3: 3 | AP3: 1 | AQ3: ОПН РТ/TEL 10/10,5 | AR3: 4752 | AS3: 45313 | AT3: 1 | AV3: 13 | AW3: «Орион-БПМ» | AX3: 16400 | AY3: 43518 | AZ3: 1 | BB3: 5 | BC3: TER_CM_16_1(220_4) | BD3: 42560 | BE3: 45826 | BG3: 17 | BH3: ОЛСП-0,63 | BI3: 39432 | BJ3: 45614 | BQ3: 9 | BR3: 3хЗНОЛП-ЭК-10 М1ТА | BS3: 96400 | BT3: 44301 | BY3: 3 | CA3: 90 | CB3: ISM15_LD_8(200_1)- 10-20/1000 | CC3: 183040 | CD3: 45826 | CE3: КСО204, КСО204м | CG3: 69 | CH3: ET-331 | CI3: 13871 | CJ3: 42363 | CK3: 2 | CP3: 5 | CR3: 2 | CS3: ФОТ КСО-204 | CT3: 42986.475 | CU3: 45736 | CW3: 22 | CX3: A1802RAL-P4G-DW-4 | CY3: 5 | CZ3: 35203 | DA3: 42432 | DC3: 48963 | DE3: 1 | DF3: 3хПатрон ПТ | DI3: 3030 | DJ3: 44638 | DL3: 1 | DM3: 1 | DN3: КСО-204м | DO3: 1ВВ | DP3: Линия | DQ3: РВЗ-10/630 | DR3: ESQ ВВ(F)-12-25/630 | DT3: АГАТ 200. А | DU3: 2 | DV3: ТЛО-10 600/5 0,5/10P | EC3: ТЗЛК-0,66-70 | EF3: 1 | EG3: Цена AL. за 1 кг | EH3: 350 | EI3: 45966 | EK3: 400 | EL3: 4х30 (Сu) | EM3: 1.08 | EN3: =EK3 -> 400 | EO3: =ROUND($EH$4*EM3*$EH$6,0) -> 1319 | EP3: Cu | EQ3: 400 | ER3: 4х40 (Ал) | ES3: 0.43 | ET3: =EQ3 -> 400 | EU3: =ROUND($EH$3*ES3*$EH$5,0) -> 188 | EV3: AL | EW3: 1 | EX3: 1 | EY3: 1
A4: 82 | B4: ТПЛ-10 75/5 0,2S/0,5S/10P | C4: 25800 | D4: 45614 | K4: 2 | L4: РВЗ-10/1000 | M4: 22568 | N4: 45680 | O4: 1 | P4: ЭБ000003956 | T4: 3 | V4: 2 | W4: CSH-120 | X4: 12810 | Y4: 42062 | AD4: 3 | AF4: 10 | AG4: 3хЗНОЛП-ЭК-6 М1ТА | AH4: 93300 | AI4: 44301 | AN4: 3 | AP4: 2 | AQ4: ОПН РТ/TEL 10/11,5 | AR4: 4752 | AS4: 45313 | AT4: 1 | AV4: 108 | AW4: TOP-200Л-22-3132 | AX4: 179071 | AY4: 45506 | AZ4: 2 | BB4: 6 | BC4: TER_CM_16_2(220_4) | BD4: 49420 | BE4: 45826 | BG4: 13 | BH4: ОЛСП-1,25 | BI4: 41952 | BJ4: 45614 | BK4: м0000004340 | BL4: м0000004341 | BO4: 3 | BQ4: 10 | BR4: 3хЗНОЛП-ЭК-6 М1ТА | BS4: 93300 | BT4: 44301 | BY4: 3 | CA4: 91 | CB4: ВВУ-СЭЩ-ПЭ-10-20/1000 | CC4: 115000 | CD4: 41134 | CE4: КСО204, КСО204м | CG4: 12 | CH4: ET431 | CI4: 14542 | CJ4: 42363 | CK4: 2 | CP4: 5 | CR4: 4 | CS4: Корпус КСО-204 | CT4: 37680 | CU4: 44301 | CW4: 20 | CX4: A1802RL-P4G-DW-4 | CY4: 5 | CZ4: 30923 | DA4: 42432 | DE4: 2 | DF4: 3хПатрон ПН | DI4: 611.79 | DJ4: 41115 | DL4: 2 | DM4: 2 | DN4: КСО-204м | DO4: 2ВВ | DP4: Линия | DQ4: РВЗ-10/630 | DR4: ESQ ВВ(F)-12-25/630 | DT4: АГАТ 200. А | DU4: 3 | DV4: ТЛО-10 600/5 0,5/10P | EC4: ТЗЛК-0,66-70 | EF4: 2 | EG4: Цена Cu за 1 кг | EH4: 1110 | EI4: 46036 | EK4: 630 | EL4: 5х40 (Сu) | EM4: 1.8 | EN4: =EK4 -> 630 | EO4: =ROUND($EH$4*EM4*$EH$6,0) -> 2198 | EP4: Cu | EQ4: 630 | ER4: 5х50 (Ал) | ES4: 0.68 | ET4: =EQ4 -> 630 | EU4: =ROUND($EH$3*ES4*$EH$5,0) -> 298 | EV4: AL | EW4: 8 | EX4: 8 | EY4: 8
A5: 83 | B5: ТПЛ-10 100/5 0,2S/0,5S/10P | C5: 25800 | D5: 45614 | K5: 3 | L5: РВФЗ-10/630 | M5: 23259.5 | N5: 45330 | O5: 1 | P5: ЭБ000003962 | T5: 3 | V5: 3 | W5: ТЗРЛ-70 | X5: 9500 | Y5: 42038 | Z5: м0000004389 | AD5: 3 | AF5: 1 | AG5: 3хЗНОЛП-ЭК-10 М1Т | AH5: 86292 | AI5: 45614 | AJ5: м0000004325 | AN5: 3 | AP5: 3 | AQ5: ОПН РТ/TEL 6/6,9 | AR5: 4032 | AS5: 45313 | AT5: 1 | AV5: 136 | AW5: VAMP50-3AAA3BBD | AX5: 78539 | AY5: 42276 | AZ5: 2 | BB5: 9 | BC5: CVM 1.1 ВЕАШ468389.001 | BD5: 26520 | BE5: 45300 | BG5: 7 | BH5: ТЛС-16 | BI5: 167000 | BJ5: 45604 | BK5: Э0000000970 | BO5: 3 | BQ5: 1 | BR5: 3хЗНОЛП-ЭК-10 М1Т | BS5: 86292 | BT5: 45614 | BU5: м0000004325 | BY5: 3 | CA5: 92 | CB5: ВВТ-10-20/1000 | CC5: 127083 | CD5: 44634 | CE5: КСО204, КСО204м | CG5: 39 | CH5: GPRS-модем Link ST100, блок питания, Антена на магнитном основании | CI5: 16000 | CJ5: 44714 | CK5: 3 | CP5: 5 | CR5: 9 | CS5: ФОТ ЩО | CT5: 21160.283 | CU5: 45736 | CW5: 34 | CX5: A1805RAL-P4GB-DW-4 | CY5: 5 | CZ5: 31610 | DA5: 42432 | DL5: 3 | DM5: 5 | DN5: КСО-204м | DO5: 5ВВ | DP5: СВ | DQ5: РВЗ-10/630 | DR5: ESQ ВВ(F)-12-25/630 | DT5: АГАТ 200. АВ | DU5: 3 | DV5: ТЛО-10 600/5 0,5/10P | EF5: 3 | EG5: Монтаж СШ (Ал.) | EH5: 1.25 | EI5: 40909 | EK5: 1000 | EL5: 6х60 (Сu) | EM5: 3.24 | EN5: =EK5 -> 1000 | EO5: =ROUND($EH$4*EM5*$EH$6,0) -> 3956 | EP5: Cu | EQ5: 1000 | ER5: 8х60 (Ал) | ES5: 1.3 | ET5: =EQ5 -> 1000 | EU5: =ROUND($EH$3*ES5*$EH$5,0) -> 569 | EV5: AL | EW5: 4 | EX5: 4 | EY5: =4*2 -> 8
A6: 84 | B6: ТПЛ-10 150/5 0,2S/0,5S/10P | C6: 25800 | D6: 45614 | K6: 4 | L6: РВФЗ-10/1000 | M6: 34320 | N6: 45330 | O6: 1 | P6: ЭБ000003961 | T6: 3 | V6: 4 | W6: ТЗРЛ-100 | X6: 10100 | Y6: 42985 | Z6: м0000004386 | AD6: 3 | AF6: 2 | AG6: 3хЗНОЛП-ЭК-6 М1Т | AH6: 83472 | AI6: 45614 | AJ6: м0000004327 | AN6: 3 | AP6: 4 | AQ6: ОПН РТ/TEL 6/7,2 | AR6: 4032 | AS6: 45313 | AT6: 1 | AV6: 103 | AW6: VAMP52 (базовый блок, 220В,RJ-45 Ethernet) | AX6: 80366.48 | AY6: 41736 | AZ6: 1 | BB6: 10 | BC6: CVM 1.2 ВЕАШ468389.001-01 | BD6: 29620 | BE6: 45300 | BG6: 8 | BH6: ТЛС-25 | BI6: 214000 | BJ6: 45604 | BK6: Э0000000910 | BO6: 3 | BQ6: 2 | BR6: 3хЗНОЛП-ЭК-6 М1Т | BS6: 83472 | BT6: 45614 | BU6: м0000004327 | BY6: 3 | CA6: 93 | CB6: ВВТ-10-20/630 | CC6: 125000 | CD6: 44747 | CE6: КСО204, КСО204м | CG6: 29 | CH6: GSM-шлюз Меркурий 228 | CI6: 10268.5 | CJ6: 42396 | CP6: 5 | CR6: 11 | CS6: Корпус КСО-393 | CT6: 10803 | CU6: 44301 | CW6: 23 | CX6: A1805RAL-P4G-DW-4 | CY6: 5 | CZ6: 29830 | DA6: 42432 | DL6: 4 | DM6: 6 | DN6: КСО-204м | DO6: 6ВВ | DP6: Ввод | DQ6: РВЗ-10/630 | DR6: ESQ ВВ(F)-12-25/630 | DT6: АГАТ 200. АВ | DU6: 2 | DV6: ТЛО-10 600/5 0,5/10P | DW6: РВЗ-10/630 | DZ6: ОЛСП1,25М2 | EC6: ТЗЛК-0,66-70 | EF6: 4 | EG6: Монтаж СШ (Сu) | EH6: 1.1 | EI6: 40909 | EW6: AL | EX6: Cu | EY6: Cu
A7: 85 | B7: ТПЛ-10 200/5 0,2S/0,5S/10P | C7: 25800 | D7: 45614 | K7: 5 | L7: ВНА-10/630 с ПР-10 | M7: 23210 | N7: 45680 | O7: 1 | P7: ЭБ000001297 | Q7: ЭБ000001298 | R7: ЭБ000001301 | S7: ЭБ000001303 | T7: 3 | V7: 5 | W7: ТЗРЛ-125 | X7: 10600 | Y7: 42038 | Z7: м0000004387 | AD7: 3 | AF7: 3 | AG7: НТМИ-10 | AH7: 26961 | AI7: 40909 | AJ7: Э0000000906 | AN7: 3 | AP7: 5 | AQ7: ОПН РB/TEL 10/12,6 | AR7: 3769 | AS7: 45699 | AT7: 1 | AV7: 147 | AW7: АГАТ 200. А | AX7: 70833 | AY7: 45677 | AZ7: 2 | BB7: 11 | BC7: КЭПС-В-6Т | BD7: 29688 | BE7: 44665 | BG7: 9 | BH7: ТЛС-40 | BI7: 235000 | BJ7: 45604 | BK7: Э0000000398 | BL7: Э0000000569 | BO7: 3 | BQ7: 3 | BR7: НТМИ-10 | BS7: 26961 | BT7: 40909 | BU7: Э0000000906 | BY7: 3 | CA7: 94 | CB7: ВВР-10-20/630 | CC7: 125000 | CD7: 44923 | CE7: КСО204, КСО204м | CG7: 60 | CH7: MES 114F (220В ПОСТОЯННОГО, ПЕРЕМЕННОГО ТОКА) | CI7: 28423.12 | CJ7: 42068 | CP7: 5 | CR7: 13 | CS7: ФОТ КСО-393 | CT7: 6823.3725 | CU7: 45736 | CW7: 73 | CX7: A1805RALXQV-P4G1B1-DW-4 | CY7: 5 | CZ7: 64740 | DA7: 43896 | DL7: 5 | DM7: 61 | DN7: КСО-204м | DO7: 6.1ВВ | DP7: Ввод | DQ7: РВЗ-10/630 | DR7: ESQ ВВ(F)-12-25/630 | DT7: АГАТ 200. АВ | DU7: 2 | DV7: ТЛО-10 600/5 0,5/10P | DW7: РВЗ-10/630 | DZ7: ОЛСП1,25М2 | EB7: ОПН РТ/TEL 10/11,5 | EC7: ТЗЛК-0,66-70 | EW7: =EW3*EU3 -> 188 | EX7: =EX3*EO3 -> 1319 | EY7: =EY3*EO3 -> 1319
A8: 86 | B8: ТПЛ-10 300/5 0,2S/0,5S/10P | C8: 24720 | D8: 45614 | K8: 6 | L8: ВНА-10/630п с ПР-10 | M8: 31390 | N8: 45680 | O8: 1 | P8: ЭБ000001304 | Q8: ЭБ000001305 | T8: 3 | V8: 6 | W8: ТЗРЛ-200 | X8: 12300 | Y8: 42038 | Z8: м0000004388 | AD8: 3 | AF8: 4 | AG8: НТМИ-6 | AH8: 24370 | AI8: 40909 | AJ8: Э0000000906 | AN8: 3 | AP8: 6 | AQ8: ОПН РB/TEL 6/7,6 | AR8: 2899 | AS8: 45699 | AT8: 1 | AV8: 163 | AW8: АГАТ 200. АВ | AX8: 79167 | AY8: 45677 | AZ8: 2 | BG8: 10 | BH8: ТЛС-63 | BI8: 285000 | BJ8: 45604 | BO8: 3 | BQ8: 4 | BR8: НТМИ-6 | BS8: 24370 | BT8: 40909 | BU8: Э0000000906 | BY8: 3 | CA8: 98 | CB8: ВВР-10-20/1000 | CC8: 123333 | CD8: 45127 | CE8: КСО204, КСО204м | CG8: 68 | CH8: PAC3200 | CI8: 32250 | CJ8: 42326 | CP8: 5 | CR8: 14 | CS8: Накладные К-104 | CT8: 164401.82 | CU8: 45736 | CW8: 21 | CX8: A1805RL-P4G-DW-4 | CY8: 5 | CZ8: 25356 | DA8: 42432 | DL8: 6 | DM8: 7 | DN8: КСО-204м | DO8: 7ВВ | DP8: Линия | DQ8: РВЗ-10/630 | DR8: ESQ ВВ(F)-12-25/630 | DT8: АГАТ 200. А | DU8: 3 | DV8: ТЛО-10 600/5 0,5/10P | DW8: РВЗ-10/630 | EC8: ТЗЛК-0,66-70 | EW8: =EW4*EU4 -> 2384 | EX8: =EX4*EO4 -> 17584 | EY8: =EY4*EO4 -> 17584
A9: 87 | B9: ТПЛ-10 400/5 0,2S/0,5S/10P | C9: 24720 | D9: 45614 | K9: 7 | L9: ВНА-10/630 СЭЩ | M9: 14723.5 | N9: 41109 | T9: 3 | V9: 7 | W9: ТЗЛЭ-125 | X9: 8800 | Y9: 42038 | Z9: м0000004383 | AD9: 3 | AF9: 5 | AG9: НАМИТ-6 | AH9: 37950 | AI9: 42075 | AJ9: м0000004410 | AN9: 3 | AP9: 7 | AQ9: РВО-10 | AR9: 1900 | AS9: 43732 | AV9: 154 | AW9: АГАТ 200. АВЭ | AX9: 39500 | AY9: 43808 | AZ9: 1 | BG9: 15 | BH9: ТМГ-16 | BI9: 100500 | BJ9: 45604 | BQ9: 5 | BR9: НАМИТ-6 | BS9: 37950 | BT9: 42075 | BU9: м0000004410 | BY9: 3 | CA9: 99 | CB9: ВВР-10-20/1600 | CC9: 132203 | CD9: 43342 | CE9: КСО204, КСО204м | CG9: 63 | CH9: Satec PM130EH Plus | CI9: 36632 | CJ9: 42075 | CP9: 5 | CR9: 15 | CS9: Корпус К-104 | CT9: 75766 | CU9: 44301 | CW9: 63 | CX9: BINOM339iU3.57I3.5 | CY9: 5 | CZ9: 151866 | DA9: 42985 | DL9: 7 | DM9: 8 | DN9: КСО-204м | DO9: 8ВВ | DP9: Линия | DQ9: РВЗ-10/630 | DR9: ESQ ВВ(F)-12-25/630 | DT9: АГАТ 200. А | DU9: 2 | DV9: ТЛО-10 600/5 0,5/10P | DW9: РВЗ-10/630 | EC9: ТЗЛК-0,66-70 | EW9: =EW5*EU5 -> 2276 | EX9: =EX5*EO5 -> 15824 | EY9: =EY5*EO5 -> 31648
A10: 88 | B10: ТПЛ-10 500/5 0,2S/0,5S/10P | C10: 24720 | D10: 45614 | K10: 8 | L10: ВНА-10/630п СЭЩ | M10: 19057.5 | N10: 41109 | T10: 3 | V10: 8 | W10: ТЗЛК-0,66-70 | X10: 1950 | Y10: 42767 | Z10: м0000004376 | AD10: 3 | AF10: 6 | AG10: НАМИТ-10 | AH10: 37950 | AI10: 42075 | AJ10: м0000004331 | AK10: м0000004332 | AN10: 3 | AP10: 8 | AQ10: РВО-6 | AR10: 1800 | AS10: 45568 | AV10: 153 | AW10: АГАТ 200. В | AX10: 70833 | AY10: 45677 | AZ10: 2 | BG10: 2 | BH10: ТМГ-25 | BI10: 111000 | BJ10: 45604 | BK10: м0000004432 | BL10: м0000004433 | BO10: 3 | BQ10: 6 | BR10: НАМИТ-10 | BS10: 37950 | BT10: 42075 | BU10: м0000004331 | BV10: м0000004332 | BY10: 3 | CA10: 100 | CB10: ISM15_Shell-31,5/2000 | CC10: 270762 | CD10: 45699 | CE10: КСО204, КСО204м | CG10: 50 | CH10: Satec PM130p plus 5-50hz-h-acdc-870 | CI10: 17082 | CJ10: 44084 | CK10: 2 | CP10: 5 | CR10: 16 | CS10: ФОТ К-104 | CT10: 102750.79 | CU10: 45736 | CW10: 54 | CX10: Альфа AV10-RAL-P14B-4 | CY10: 5 | CZ10: 15695 | DA10: 42432 | DL10: 8 | DM10: 81 | DN10: КСО-204м | DO10: 8.1ВВ | DP10: Линия | DQ10: РВЗ-10/630 | DR10: ESQ ВВ(F)-12-25/630 | DT10: АГАТ 200. А | DU10: 2 | DV10: ТЛО-10 600/5 0,5/10P | DW10: РВЗ-10/630 | EB10: ОПН РТ/TEL 10/11,5 | EC10: ТЗЛК-0,66-70 | EW10: =SUM(EW7:EW9) -> 4848 | EX10: =SUM(EX7:EX9) -> 34727 | EY10: =SUM(EY7:EY9) -> 50551
A11: 89 | B11: ТПЛ-10 600/5 0,2S/0,5S/10P | C11: 24720 | D11: 45614 | K11: 9 | L11: Зазем РВЗ-И-10/31,5-150 | M11: 34717.826 | N11: 43536 | O11: 1 | T11: 3 | V11: 10 | W11: ТЗЛКР-0,66-70 | X11: 6095 | Y11: 45614 | AF11: 7 | AG11: ЗНОЛП-ЭК-6 М1 | AH11: 14800 | AI11: 44406 | AN11: 3 | AP11: 9 | AQ11: ОПН 10кВ | AR11: 1410 | AS11: 41746 | AV11: 162 | AW11: АГАТ 200. ДЭ | AX11: 100000 | AY11: 45888 | AZ11: 1 | BG11: 3 | BH11: ТМГ-40 | BI11: 125300 | BJ11: 45604 | BK11: Э0000000973 | BO11: 3 | BQ11: 7 | BR11: ЗНОЛП-ЭК-6 М1 | BS11: 14800 | BT11: 44406 | BY11: 3 | CA11: 104 | CB11: VF12-S-10-20/630 | CC11: 132990 | CD11: 44946 | CE11: КСО204, КСО204м | CG11: 55 | CH11: SDM-TC65 (с блоком питания и антеной) | CI11: 7500 | CJ11: 41736 | CK11: 1 | CP11: 5 | CR11: 18 | CS11: Тележка К-104 | CT11: 87224 | CU11: 45736 | CW11: 53 | CX11: Матрица NP 73L.3-5-2 | CY11: 5 | CZ11: 8563 | DA11: 42068 | DL11: 9 | DM11: 9 | DN11: КСО-204 | DO11: 9-400 | DP11: Линия | DQ11: РВЗ-10/630 | EA11: 3хПатрон ПТ
A12: 90 | B12: ТПЛ-10 800/5 0,2S/0,5S/10P | C12: 24720 | D12: 45614 | K12: 10 | L12: ЗР-10 | M12: 11519 | N12: 45680 | O12: 1 | P12: ЭБ000001601 | T12: 3 | V12: 11 | W12: ТЗЛКР-0,66-100 | X12: 6670 | Y12: 45614 | AF12: 8 | AG12: ЗНОЛП-ЭК-10 М1 | AH12: 15700 | AI12: 44406 | AN12: 3 | AP12: 10 | AQ12: ОПН 6кВ | AR12: 1410 | AS12: 41746 | AV12: 159 | AW12: АГАТ-100 | AX12: 45833 | AY12: 45677 | BG12: 4 | BH12: ТМГ-63 | BI12: 147600 | BJ12: 45604 | BK12: м0000004435 | BL12: м0000004436 | BO12: 3 | BQ12: 8 | BR12: ЗНОЛП-ЭК-10 М1 | BS12: 15700 | BT12: 44406 | BY12: 3 | CA12: 114 | CB12: Вакуумный контактор UVC 64 CX1 стац 400А | CC12: 73580 | CD12: 44267 | CE12: КСО204 | CG12: 80 | CH12: SIMEAS 7KG77500AA03-0AA0 | CI12: 36500 | CJ12: 42811 | CP12: 5 | CR12: 19 | CS12: Корпус КСО-211 | CT12: 105556 | CU12: 44301 | CW12: 40 | CX12: Матрица NP541.58Т, 0,5S/2,0 | CY12: 5 | CZ12: 7622 | DA12: 41164 | DL12: 10 | DM12: 10 | DN12: КСО-204 | DO12: 10 | DP12: Линия | DQ12: РВЗ-10/630 | DW12: ВНА-10/630п с ПР-10
A13: 91 | B13: ТПЛ-10 1000/5 0,2S/0,5S/10P | C13: 24720 | D13: 45614 | K13: 11 | L13: РВ-10/630 | M13: 14950 | N13: 45680 | O13: 1 | P13: ЭБ000003954 | T13: 3 | V13: 12 | W13: ТЗЛКР-0,66-125 | X13: 8165 | Y13: 45614 | AG13: 3хЗНОЛП-ЭК-3_М1 | AH13: 42102 | AN13: 3 | AP13: 12 | AQ13: ОПН KP/TEL 6/6,9 | AR13: 2888 | AS13: 45313 | AT13: 1 | AV13: 175 | AW13: Алтей-01-220-4IT-4U-IO-RSTX-Arc-IoT | AX13: 175250 | AY13: 45699 | BG13: 14 | BH13: ТСКС-16 | BI13: 146500 | BJ13: 45604 | BO13: 3 | BR13: 3хЗНОЛП-ЭК-3_М1 | BS13: 42102 | BY13: 3 | CA13: 115 | CB13: ВЭ/TER_VCB15_LD8_RD-20/1000 | CC13: 308116 | CD13: 45624 | CE13: К104 | CG13: 49 | CH13: SPA-ZC17MM2A | CI13: 33248 | CJ13: 41522 | CP13: 5 | CR13: 20 | CS13: ФОТ КСО-211 | CT13: 55803.037 | CU13: 45736 | CW13: 52 | CX13: Матрица NP73e.3-9-1 | CY13: 5 | CZ13: 22000 | DA13: 41736 | DL13: 11 | DM13: 12 | DN13: КСО-204 | DO13: 12-630ТН | DP13: ТН | DQ13: РВЗ-10/630 | DT13: АГАТ 200. В | DW13: РВФЗ-10/630 | DY13: 3хЗНОЛП-ЭК-10 М1Т | EB13: ОПН РТ/TEL 10/11,5
A14: 92 | B14: ТПЛ-10 1500/5 0,2S/0,5S/10P | C14: 24720 | D14: 45614 | K14: 12 | L14: РВЗ-10/400 | M14: 16367 | N14: 45680 | O14: 1 | T14: 3 | V14: 13 | W14: ТЗЛКР-0,66-200 | X14: 10120 | Y14: 45614 | AG14: НОЛ-ЭК-10 М1 6000/100-0,5-50 | AH14: 19000 | AI14: 44476 | AN14: 3 | AP14: 13 | AQ14: ОПН KP/TEL 10/11,5 | AR14: 4032 | AS14: 45313 | AT14: 1 | AV14: 172 | AW14: Бастион МПЗ-03 | AX14: 127500 | AY14: 45519 | AZ14: 1 | BG14: 5 | BH14: ТСКС-25 | BI14: 213250 | BJ14: 45604 | BK14: м0000004490 | BO14: 3 | BR14: НОЛ-ЭК-10 М1 6000/100-0,5-50 | BS14: 19000 | BT14: 44476 | BY14: 3 | CA14: 116 | CB14: ВЭ/TER_VCB15_LD8_RD-20/630 | CC14: 308116 | CD14: 45624 | CE14: К104 | CG14: 73 | CH14: TER_Cbunit_ManGen_1 | CI14: 21665.52 | CJ14: 45407 | CK14: 1 | CP14: 5 | CR14: 21 | CS14: RamBlock | CT14: 68900 | CU14: 42034 | CW14: 2 | CX14: Меркурий 230 AR-00 С (R) | CY14: 5 | CZ14: 4091 | DA14: 44314 | DL14: 12 | DM14: 121 | DN14: КСО-204 | DO14: 12.1-630ТН | DP14: ТН | DQ14: РВЗ-10/630 | DT14: АГАТ 200. В | DW14: РВФЗ-10/630 | DY14: 3хЗНОЛП-ЭК-10 М1Т | EB14: ОПН РТ/TEL 10/11,5
A15: 93 | B15: ТПЛ-10 50/5 0,5S/0,5/10P | C15: 24720 | D15: 45614 | K15: 13 | L15: ВНВР-10/630-20 | M15: 53991.3 | N15: 45356 | O15: 1 | T15: 3 | V15: 14 | W15: ТЗЛК-0,66-100 | X15: 5290 | Y15: 45614 | Z15: м0000004376 | AD15: 3 | AG15: НОЛ-ЭК-10 М1 3000/100-0,5-50 | AH15: 15000 | AI15: 43115 | AN15: 3 | AP15: 14 | AQ15: ОПНп-35/40,5/10 | AR15: 13566 | AS15: 42807 | AT15: 2 | AV15: 174 | AW15: Бастион МПЗ-03pro | AX15: 118333 | AY15: 45519 | AZ15: 1 | BG15: 6 | BH15: ТСКС-40 | BI15: 270400 | BJ15: 41076 | BK15: м0000004491 | BL15: Э0000000520 | BO15: 3 | BR15: НОЛ-ЭК-10 М1 3000/100-0,5-50 | BS15: 15000 | BT15: 43115 | BY15: 3 | CA15: 117 | CB15: ВЭ/TER_VCB15_Shell2_RD-31,5/1600 | CC15: 448986 | CD15: 45624 | CE15: К104 | CG15: 51 | CH15: UMG 508 | CI15: 45000 | CJ15: 41715 | CK15: 3 | CP15: 5 | CR15: 22 | CS15: Корпус ПКУ | CT15: 34740 | CU15: 44301 | CW15: 4 | CX15: Меркурий 230 АRT-00 P(Q)С(R)SIDN | CY15: 5 | CZ15: 5653 | DA15: 44314 | DL15: 13 | DM15: 13 | DN15: КСО-204м | DO15: 13-400ТН | DP15: ТН | DQ15: РВЗ-10/630 | DT15: АГАТ 200. В | DW15: ЗР-10 | DY15: 3хЗНОЛП-ЭК-10 М1Т | EB15: ОПН РТ/TEL 10/11,5
A16: 94 | B16: ТПЛ-10 75/5 0,5S/0,5/10P | C16: 24720 | D16: 45614 | K16: 14 | L16: ВНВР-10/630-20п | M16: 70216.3 | N16: 45356 | O16: 1 | T16: 3 | V16: 15 | W16: ТЗЛК-0,66-125 | X16: 6670 | Y16: 45614 | Z16: м0000004376 | AD16: 3 | AG16: НАЛИ-НТЗ-6 | AH16: 80600 | AI16: 45572 | AN16: 3 | AP16: 15 | AQ16: ОПНп-27,5/30/10 | AR16: 12698 | AS16: 42807 | AT16: 2 | AV16: 173 | AW16: Бастион МПЗ-03ТН | AX16: 121667 | AY16: 45519 | AZ16: 1 | BR16: НАЛИ-НТЗ-6 | BS16: 80600 | BT16: 45572 | BY16: 3 | CA16: 118 | CB16: Выдвижной элемент К-104 | CC16: 56085 | CD16: 43342 | CE16: К104 | CG16: 40 | CH16: АВР ATS021 (1SDA065523R1) | CI16: 44103 | CJ16: 41304 | CK16: 2 | CP16: 5 | CR16: 23 | CS16: Накладные ПКУ | CT16: 51848.37 | CU16: 45736 | CW16: 8 | CX16: Меркурий 230 АRT-00 P(Q)С(R)SIGDN | CY16: 5 | CZ16: 18000.58 | DA16: 40909 | DL16: 14 | DM16: 14 | DN16: КСО-204м | DO16: 14-400ТН | DP16: ТН | DQ16: РВЗ-10/630 | DT16: АГАТ 200. В | DY16: 3хЗНОЛП-ЭК-10 М1Т | EB16: ОПН РТ/TEL 10/11,5
A17: 95 | B17: ТПЛ-10 100/5 0,5S/0,5/10P | C17: 24720 | D17: 45614 | K17: 17 | L17: РВЗ-СЭЩ-10/1600 | M17: 24200 | N17: 41711 | T17: 3 | V17: 16 | W17: ТЗЛК-0,66-200 | X17: 8970 | Y17: 45614 | Z17: м0000004376 | AD17: 3 | AG17: НАЛИ-НТЗ-10 | AH17: 80600 | AI17: 45572 | AN17: 3 | AP17: 16 | AQ17: ОПНп-3/550/3,6 | AR17: 1690 | AS17: 43224 | AV17: 24 | AW17: Без МПЗ | AX17: 10000 | AY17: 41068 | BR17: НАЛИ-НТЗ-10 | BS17: 80600 | BT17: 45572 | BY17: 3 | CA17: 119 | CB17: ВЭ/VD4-10-25/1000 | CC17: 207500 | CD17: 41432 | CE17: К104 | CG17: 52 | CH17: АВР-3/3-22 | CI17: 11500 | CJ17: 44714 | CP17: 5 | CR17: 24 | CS17: ФОТ ПКУ | CT17: 32073.93 | CU17: 45736 | CW17: 3 | CX17: Меркурий 230 АRT-00 С (R)N | CY17: 5 | CZ17: 6113 | DA17: 45406 | DL17: 15 | DM17: 15 | DN17: КСО-204м | DO17: 15-400ТСН | DP17: ТСН | DQ17: РВЗ-10/630 | DZ17: ТМГ-25 | EA17: 3хПатрон ПТ
A18: 96 | B18: ТПЛ-10 150/5 0,5S/0,5/10P | C18: 24720 | D18: 45614 | K18: 18 | L18: РВФЗ-СЭЩ-10/1600 | M18: 24200 | N18: 41711 | T18: 3 | V18: 17 | W18: ТЗЛК-0,66-70 | X18: 5060 | Y18: 45614 | AG18: НАЛИ-ЭК 6 М4 | AH18: 92690 | AI18: 45614 | AN18: 3 | AP18: 17 | AQ18: ОПН-П-10/12/10/550 | AR18: 1900 | AS18: 45693 | AT18: 1 | AV18: 141 | AW18: БЗП-01 | AX18: 35000 | AY18: 42611 | AZ18: 2 | BR18: НАЛИ-ЭК 6 М4 | BS18: 92690 | BT18: 45614 | BY18: 3 | CA18: 120 | CB18: ВЭ К-104М с ВВР-10-20/1000 | CC18: 272600 | CD18: 45882 | CE18: К104 | CG18: 7 | CH18: Амперметр | CI18: 1596 | CJ18: 44407 | CL18: ЭБ000000360 | CM18: ЭБ000000361 | CN18: ЭБ000000367 | CO18: ЭБ000000371 | CP18: 5 | CR18: 25 | CS18: OptiboxM | CT18: 37680 | CU18: 43285 | CW18: 6 | CX18: Меркурий 230 АRT2-00 P(Q)С(R)SIDN | CY18: 5 | CZ18: 8926.32 | DA18: 40909 | DL18: 16 | DM18: 31 | DN18: КСО-204м | DO18: 31-400 | DP18: ЗСШ | DW18: ЗР-10
A19: 97 | B19: ТПЛ-10 200/5 0,5S/0,5/10P | C19: 24720 | D19: 45614 | K19: 19 | L19: РВЗ-10/1600 | M19: 45050.8 | N19: 45702 | T19: 3 | AG19: НАЛИ-ЭК 10 М4 | AH19: 92690 | AI19: 45614 | AN19: 3 | AP19: 18 | AQ19: ОПН-П-6/7.2/10/550 | AR19: 1900 | AS19: 45693 | AT19: 1 | AV19: 29 | AW19: БИМ 2130.55 АДР01 | AX19: 47500 | AY19: 40959 | BR19: НАЛИ-ЭК 10 М4 | BS19: 92690 | BT19: 45614 | BY19: 3 | CA19: 121 | CB19: ВЭ К-104М с ВВР-10-20/1600 | CC19: 296200 | CD19: 45882 | CE19: К104 | CG19: 97 | CH19: Амперметр цифровой AD-721 | CI19: 1526 | CJ19: 44460 | CP19: 5 | CR19: 26 | CS19: ЩО-70-1 | CT19: 16660 | CU19: 45736 | CW19: 9 | CX19: Меркурий 230 АRT2-00 PСSIGDN | CY19: 5 | CZ19: 20000.36 | DA19: 40909 | DL19: 17 | DM19: 41 | DN19: КСО-204м | DO19: 4.1ВВ | DP19: СВ | DQ19: РВЗ-10/630 | DR19: ESQ ВВ(F)-12-25/630 | DT19: Сириус - 2-С-БПТ | DU19: 2 | DV19: ТЛО-10 600/5 0,5/10P
A20: 98 | B20: ТПЛ-10 300/5 0,5S/0,5/10P | C20: 24720 | D20: 45614 | K20: 20 | L20: РВФЗ-10/1600 | M20: 75900 | N20: 45702 | T20: 3 | AG20: НАЛИ-ЭК-6-М6П—0.5/3P-75/400-6000-100/100 У2 (антирезонансный) | AH20: 97865 | AI20: 45614 | AN20: 3 | AV20: 30 | AW20: БИМ 5160.00 АДР01С1 | AX20: 24698 | AY20: 40959 | BR20: НАЛИ-ЭК-6-М6П—0.5/3P-75/400-6000-100/100 У2 (антирезонансный) | BS20: 97865 | BT20: 45614 | BY20: 3 | CA20: 122 | CB20: ВЭ К-104М с ВВР-10-20/630 | CC20: 261000 | CD20: 45882 | CE20: К104 | CG20: 19 | CH20: Амперметр цифровой ЩП02М 100/5 с RS485 | CI20: 8112.5 | CJ20: 41109 | CP20: 5 | CR20: 27 | CS20: ЩО-70-2 | CT20: 16660 | CU20: 45736 | CW20: 61 | CX20: Меркурий 230 АRTM2-00 RB.R | CY20: 5 | CZ20: 13480 | DA20: 44314 | DL20: 18 | DM20: 122 | DN20: КСО-204м | DO20: 12.2-630ТН | DP20: ТН | DQ20: РВЗ-10/630 | DT20: АГАТ 200. В | DY20: 3хЗНОЛП-ЭК-10 М1Т | EB20: ОПН РТ/TEL 10/11,5
A21: 99 | B21: ТПЛ-10 400/5 0,5S/0,5/10P | C21: 24720 | D21: 45614 | AG21: НАЛИ-ЭК–10–М6П–0,5/3P–30/50–10000–100/100 УХЛ3 (антирезонансный) | AH21: 97865 | AI21: 45614 | AN21: 3 | AV21: 164 | AW21: БМРЗ-100 | AX21: 78960 | AY21: 44945 | AZ21: 1 | BR21: НАЛИ-ЭК–10–М6П–0,5/3P–30/50–10000–100/100 УХЛ3 (антирезонансный) | BS21: 97865 | BT21: 45614 | BY21: 3 | CA21: 123 | CB21: ВЭ К-104М с ВВР-10-31,5/1600 | CC21: 386685 | CD21: 45882 | CE21: К104 | CG21: 27 | CH21: АСЕ-949-2 | CI21: 11127.14 | CJ21: 42068 | CP21: 5 | CR21: 28 | CS21: ЩО-70-3 | CT21: 16660 | CU21: 45736 | CW21: 1 | CX21: Меркурий 230 АМ-00 | CY21: 5 | CZ21: 2302 | DA21: 44314 | DL21: 19 | DM21: 151 | DN21: КСО-204м | DO21: 15.1-400ТСН | DP21: ТСН | DQ21: РВЗ-10/630 | DZ21: ТЛС-16 | EA21: 3хПатрон ПТ
A22: 100 | B22: ТПЛ-10 500/5 0,5S/0,5/10P | C22: 24720 | D22: 45614 | AV22: 38 | AW22: БМРЗ-101-2-Д-КЛ-01 | AX22: 107376 | AY22: 44945 | AZ22: 1 | CA22: 124 | CB22: Shell2-1 2000A на тележке К-104 | CC22: 240230 | CD22: 43360 | CE22: К104 | CG22: 3 | CH22: БАВ/TEL-220-02 | CI22: 6142.5 | CJ22: 41261 | CP22: 5 | CR22: 29 | CS22: ЩО-НКУ | CT22: 16660 | CU22: 45736 | CW22: 77 | CX22: Меркурий 234 ARTMX2-03 (D)PBR.G | CY22: 5 | CZ22: 18616 | DA22: 45310 | DL22: 21 | DM22: 241 | DN22: КСО-204м | DO22: 24.1-600 | DP22: СР | DQ22: РВЗ-10/630
A23: 101 | B23: ТПЛ-10 600/5 0,5S/0,5/10P | C23: 24720 | D23: 45614 | AV23: 62 | AW23: БМРЗ-102-2-Д-КЛ-01 | AX23: 107376 | AY23: 44945 | AZ23: 1 | CA23: 126 | CB23: ВЭ/TER_VCB15_Shell2_RD-31,5/2000 | CC23: 493479 | CD23: 45624 | CE23: К104 | CG23: 6 | CH23: БИН | CI23: 12900 | CJ23: 44662 | CP23: 5 | CR23: 31 | CS23: Корпус КСО-204м | CT23: 37680 | CU23: 44301 | CW23: 57 | CX23: Меркурий 234 АRT-00 P | CY23: 5 | CZ23: 6250 | DA23: 44314 | DL23: 22 | DM23: 282 | DN23: КСО-204м | DO23: 28.2А | DP23: СР+ШСН | DQ23: РВЗ-10/630 | ED23: ШСН
A24: 102 | B24: ТПЛ-10 800/5 0,5S/0,5/10P | C24: 24720 | D24: 45614 | AV24: 63 | AW24: БМРЗ-103-2-Д-ВВ-01 | AX24: 107376 | AY24: 44945 | AZ24: 1 | CA24: 135 | CB24: Касетный элемент КСО211 | CC24: 29200 | CD24: 41233 | CE24: КСО211 | CG24: 117 | CH24: БИН СКВН-2 | CI24: 6530 | CJ24: 45904 | CP24: 5 | CR24: 32 | CS24: Накладные КСО-211 Линия | CT24: 128902.1 | CU24: 45736 | CW24: 58 | CX24: Меркурий 234 АRT2-00 P | CY24: 5 | CZ24: 10031 | DA24: 44314 | DL24: 23 | DM24: 283 | DN24: КСО-204м | DO24: 28.3А | DP24: СР+ШСН | DQ24: РВЗ-10/630 | ED24: ШСН
A25: 103 | B25: ТПЛ-10 1000/5 0,5S/0,5/10P | C25: 24720 | D25: 45614 | AV25: 37 | AW25: БМРЗ-103-2-Д-СВ-01 | AX25: 107376 | AY25: 44945 | AZ25: 1 | CA25: 136 | CB25: КВЭ (Бриз) ВВТ-10-20/630 | CC25: 141629.2 | CD25: 43514 | CE25: КСО211 | CG25: 2 | CH25: БМВ-12/28-02 | CI25: 10845 | CJ25: 41261 | CL25: ЭБ000000508 | CP25: 5 | CR25: 33 | CS25: Накладные КСО-211 Ввод | CT25: 128902.1 | CU25: 45736 | CW25: 72 | CX25: Меркурий 234 АRTM(Х)2-00 (D)PBR.G | CY25: 5 | CZ25: 17540 | DA25: 45406 | DL25: 24 | DM25: 32 | DN25: КСО-204м | DO25: 31-400 | DP25: ЗСШ | DW25: ЗР-10
A26: 104 | B26: ТПЛ-10 1500/5 0,5S/0,5/10P | C26: 24720 | D26: 45614 | AV26: 89 | AW26: БМРЗ-104-2-Д-ТН-01 | AX26: 107376 | AY26: 44945 | AZ26: 1 | CA26: 137 | CB26: КВЭ (Бриз) ВВТ-10-20/1000 | CC26: 146458.3 | CD26: 43514 | CE26: КСО211 | CG26: 100 | CH26: БП 220/24-2 | CI26: 12480 | CJ26: 44945 | CP26: 5 | CR26: 34 | CS26: Накладные КСО-211 Линия к ТР | CT26: 128902.1 | CU26: 45736 | CW26: 56 | CX26: Меркурий 234 АRTM2-03 PBR.R | CY26: 5 | CZ26: 12912 | DA26: 44715 | DL26: 25 | DM26: 84 | DN26: КСО-204м | DO26: 8.4ВВ | DP26: Ввод | DQ26: РВ-10/630 | DR26: ESQ ВВ(F)-12-25/630 | DT26: АГАТ 200. АВ | DU26: 2 | DV26: ТЛО-10 600/5 0,5/10P | DW26: ЗР-10 | DX26: СЭТ-4ТМ.03М.05 | DY26: 3хЗНОЛП-ЭК-10 М1ТА | EB26: ОПН РТ/TEL 10/11,5
A27: 105 | B27: ТПЛ-10 50/5 0,5/10P | C27: 20760 | D27: 45614 | AV27: 129 | AW27: БМРЗ-121-2-Д-КЛ-01 | AX27: 127008 | AY27: 44945 | AZ27: 1 | CA27: 140 | CB27: КВЭ/VF-12-S-10-20/630 | CC27: 140859 | CD27: 43536 | CE27: КСО211 | CG27: 99 | CH27: БПК-5М-Т | CI27: 69120 | CJ27: 44945 | CP27: 5 | CR27: 35 | CS27: Накладные КСО-211 ТН | CT27: 128902.1 | CU27: 45736 | CW27: 78 | CX27: Милур 307S.11-GRR-2 | CY27: 5 | CZ27: 21580 | DA27: 45693 | DL27: 26 | DM27: 311110 | DN27: КСО-393 | DO27: 3НПО | DP27: Линия | DR27: Вакуумный контактор UVC 64 CX1 стац 400А | DW27: РВЗ-10/630 | EA27: 3хПатрон ПТ | EB27: ОПН РТ/TEL 10/11,5
A28: 106 | B28: ТПЛ-10 75/5 0,5/10P | C28: 20760 | D28: 45614 | AV28: 130 | AW28: БМРЗ-122-2-Д-КЛ-01 | AX28: 127008 | AY28: 44945 | AZ28: 1 | CA28: 141 | CB28: КВЭ/VF-12-S-10-20/800 | CC28: 150441 | CD28: 43536 | CE28: КСО211 | CG28: 98 | CH28: БПК-5-Т | CI28: 57840 | CJ28: 44945 | CP28: 5 | CR28: 36 | CS28: Накладные КСО-211 ТСН | CT28: 128902.1 | CU28: 45736 | CW28: 49 | CX28: МИР С-03.05T-Е-R- 1Т | CY28: 5 | CZ28: 17400 | DA28: 41471 | DL28: 27 | DM28: 39302 | DN28: КСО-393 | DO28: 02 | DP28: Линия | DQ28: РВЗ-10/630
A29: 107 | B29: ТПЛ-10 100/5 0,5/10P | C29: 20760 | D29: 45614 | AV29: 128 | AW29: БМРЗ-123-2-Д-ВВ-01 | AX29: 127008 | AY29: 44945 | AZ29: 1 | CA29: 142 | CB29: КВЭ/VF-12-S-10-20/1000 | CC29: 152232 | CD29: 43536 | CE29: КСО211 | CG29: 44 | CH29: БПТМ 610-01 | CI29: 7936 | CJ29: 41359 | CK29: 2 | CP29: 5 | CR29: 37 | CS29: Накладные КСО-211 СВ | CT29: 128902.1 | CU29: 45736 | CW29: 48 | CX29: МИР С-03.05T-ЕВ-R-1Т (м) | CY29: 5 | CZ29: 8250 | DA29: 41471 | DL29: 28 | DM29: 39303 | DN29: КСО-393 | DO29: 03 | DP29: Линия | DQ29: ВНА-10/630 с ПР-10
A30: 108 | B30: ТПЛ-10 150/5 0,5/10P | C30: 20760 | D30: 45614 | AV30: 131 | AW30: БМРЗ-123-2-Д-СВ-01 | AX30: 127008 | AY30: 44945 | AZ30: 1 | CA30: 143 | CB30: КВЭ/VF-12-S-10-25/630 | CC30: 153437 | CD30: 43536 | CE30: КСО211 | CG30: 74 | CH30: БУАВР СР1007 | CI30: 40085 | CJ30: 42513 | CK30: 3 | CP30: 5 | CR30: 38 | CS30: Накладные КСО-211 СР | CT30: 128902.1 | CU30: 45736 | CW30: 47 | CX30: МИР С-03.05Т-EBN-R-H | CY30: 5 | CZ30: 9526 | DA30: 41471 | DL30: 29 | DM30: 39304 | DN30: КСО-393 | DO30: 04 | DP30: Линия к ТР | DQ30: ВНА-10/630п с ПР-10 | EA30: 3хПатрон ПТ
A31: 109 | B31: ТПЛ-10 200/5 0,5/10P | C31: 20760 | D31: 45614 | AV31: 132 | AW31: БМРЗ-124-2-Д-ТН-01 | AX31: 127008 | AY31: 44945 | AZ31: 1 | CA31: 144 | CB31: КВЭ/VF-12-S-10-25/800 | CC31: 155000 | CD31: 43536 | CE31: КСО211 | CG31: 8 | CH31: Вольтметр | CI31: 1439 | CJ31: 44354 | CL31: ЭБ000000717 | CP31: 5 | CR31: 39 | CS31: Накладные КСО-204 Линия | CT31: 121319.1 | CU31: 45736 | CW31: 76 | CX31: МИР С-07.05S-230-5(10)-R-S2T2LQ-D | CY31: 5 | CZ31: 18720 | DA31: 45278 | DL31: 30 | DM31: 393041 | DN31: КСО-393 | DO31: 04Н | DP31: Линия | DQ31: ВНА-10/630п с ПР-10 | DU31: 2 | DV31: ТЛО-10 150/5 0,5/10P | EA31: 3хПатрон ПТ
A32: 110 | B32: ТПЛ-10 300/5 0,5/10P | C32: 19800 | D32: 45614 | AV32: 116 | AW32: БМРЗ-152-2-Д-БСК-01 | AX32: 164200 | AY32: 45331 | AZ32: 1 | CA32: 145 | CB32: КВЭ/VF-12-S-10-25/1000 | CC32: 157443 | CD32: 43536 | CE32: КСО211 | CG32: 31 | CH32: вольтметр Shnaider СВ3021-250 | CI32: 7680 | CJ32: 41164 | CP32: 5 | CR32: 40 | CS32: Накладные КСО-204 Ввод | CT32: 121319.1 | CU32: 45736 | CW32: 15 | CX32: НЕВА СТ413 545 BSPIO22-G3 | CY32: 5 | CZ32: 12250 | DA32: 45449 | DL32: 31 | DM32: 39311 | DN32: КСО-393 | DO32: 11 | DP32: ТН | DQ32: РВЗ-10/630 | DY32: 3хЗНОЛП-ЭК-10 М1Т
A33: 111 | B33: ТПЛ-10 400/5 0,5/10P | C33: 19800 | D33: 45614 | AV33: 112 | AW33: БМРЗ-152-2-Д-ВВ-01 | AX33: 224200 | AY33: 45831 | AZ33: 1 | CA33: 146 | CB33: ВЭ/ВБМ-10-20/630 | CC33: 214830 | CD33: 43605 | CE33: К104 | CG33: 20 | CH33: Вольтметр цифровой ЩП02M-11кВ/100В с RS485 | CI33: 8112.5 | CJ33: 41109 | CP33: 5 | CR33: 41 | CS33: Накладные КСО-204 Линия к ТР | CT33: 121319.1 | CU33: 45736 | CW33: 14 | CX33: Протон-К ЦМ-02-А-2-234 | CY33: 5 | CZ33: 15000 | DA33: 41039 | DL33: 32 | DM33: 39314 | DN33: КСО-393 | DO33: 14 | DP33: СР | DQ33: РВЗ-10/630
A34: 112 | B34: ТПЛ-10 500/5 0,5/10P | C34: 19800 | D34: 45614 | AV34: 115 | AW34: БМРЗ-152-2-Д-КЛ-01 | AX34: 224200 | AY34: 45831 | AZ34: 1 | CA34: 147 | CB34: VM12-10-20/1000 | CC34: 117020 | CD34: 45300 | CE34: КСО204, КСО204м | CG34: 95 | CH34: Дуга-0, 3хдатчика дуги | CI34: 49080 | CJ34: 45616 | CK34: 1 | CP34: 5 | CR34: 42 | CS34: Накладные КСО-204 ТН | CT34: 121319.1 | CU34: 45736 | CW34: 16 | CX34: Протон-К ЦМ-02-А-3-234 | CY34: 5 | CZ34: 15000 | DA34: 41057
A35: 113 | B35: ТПЛ-10 600/5 0,5/10P | C35: 19800 | D35: 45614 | AV35: 142 | AW35: БМРЗ-152-2-Д-КСЗ-01 | AX35: 182112 | AY35: 45197 | AZ35: 1 | CA35: 148 | CB35: ВБП-10-20/630 | CC35: 154312 | CD35: 43929 | CE35: КСО204, КСО204м | CG35: 105 | CH35: Дуговая защита Агат-Дуга | CI35: 35833 | CJ35: 45677 | CP35: 5 | CR35: 43 | CS35: Накладные КСО-204 ТСН | CT35: 121319.1 | CU35: 45736 | CW35: 19 | CX35: Протон-К ЦМ-02-К-1-234 | CY35: 5 | CZ35: 30255 | DA35: 41057
A36: 114 | B36: ТПЛ-10 800/5 0,5/10P | C36: 19800 | D36: 45614 | AV36: 113 | AW36: БМРЗ-152-2-Д-СВ-01 | AX36: 164200 | AY36: 45331 | AZ36: 1 | CA36: 149 | CB36: КЭПС-КМ 10-20/1000 | CC36: 156496 | CD36: 45357 | CE36: КСО204, КСО204м | CG36: 107 | CH36: Дуговая защита Бастион-ДЗ | CI36: 14500 | CJ36: 45519 | CK36: 1 | CP36: 5 | CR36: 44 | CS36: Накладные КСО-204 СВ | CT36: 121319.1 | CU36: 45736 | CW36: 18 | CX36: Протон-К ЦМ-02-К-2-234 | CY36: 5 | CZ36: 30255 | DA36: 41057
A37: 115 | B37: ТПЛ-10 1000/5 0,5/10P | C37: 19800 | D37: 45614 | AV37: 114 | AW37: БМРЗ-152-2-Д-ТН-01 | AX37: 164200 | AY37: 45331 | AZ37: 1 | CA37: 150 | CB37: КВЭ/VF12-S-10-20/1600 | CC37: 194406 | CD37: 44705 | CE37: КСО211 | CG37: 115 | CH37: Дуговая защита Лайм с 3 датчиками дуги | CI37: 27750 | CJ37: 45742 | CP37: 5 | CR37: 45 | CS37: Накладные КСО-204 СР | CT37: 121319.1 | CU37: 45736 | CW37: 17 | CX37: Протон-К ЦМ-02-Т-2-234 | CY37: 5 | CZ37: 24921 | DA37: 41057
A38: 116 | B38: ТПЛ-10 1500/5 0,5/10P | C38: 19800 | D38: 45614 | AV38: 144 | AW38: БМРЗ-158-ГР | AX38: 225800 | AY38: 45831 | AZ38: 2 | CA38: 151 | CB38: ВЭ/ВБСК2-10-20/1000 | CC38: 166666 | CD38: 44748 | CE38: К104 | CG38: 106 | CH38: Дуговая защита МИКО-ДЗ ( в комплекте с 3 датчиками ВОД) | CI38: 35083 | CJ38: 45447 | CK38: 1 | CP38: 5 | CR38: 46 | CS38: Накладные КСО-204м Линия | CT38: 121319.1 | CU38: 45736 | CW38: 25 | CX38: ПСЧ-3АР.07.132.3 | CY38: 5 | CZ38: 3189 | DA38: 40909
A39: 117 | B39: ТПЛ-10 50/5 0,5S/10P | C39: 23040 | D39: 45614 | AV39: 140 | AW39: БМЦС-40-21 | AX39: 129600 | AY39: 44945 | AZ39: 1 | CA39: 152 | CB39: ВБСК-10-20/1000 | CC39: 125000 | CD39: 44748 | CE39: КСО204 | CG39: 26 | CH39: Е3855С | CI39: 5518 | CJ39: 41151 | CP39: 5 | CR39: 47 | CS39: Накладные КСО-204м Ввод | CT39: 121319.1 | CU39: 45736 | CW39: 55 | CX39: ПСЧ-3ар.07д.132.3 | CY39: 5 | CZ39: 2668 | DA39: 42209
A40: 118 | B40: ТПЛ-10 75/5 0,5S/10P | C40: 23040 | D40: 45614 | AV40: 28 | AW40: БЭ2502А0103 (ЭКРА) | AX40: 71400 | AY40: 43242 | AZ40: 2 | CA40: 153 | CB40: VF12-S-10-20/1600 | CC40: 194920 | CD40: 44946 | CE40: КСО204, КСО204м | CG40: 13 | CH40: Е842/1 | CI40: 1700 | CJ40: 41080 | CP40: 5 | CR40: 48 | CS40: Накладные КСО-204м Линия к ТР | CT40: 121319.1 | CU40: 45736 | CW40: 42 | CX40: ПСЧ-3АРТ.08 | CY40: 5 | CZ40: 3189 | DA40: 40909
...

Sheet Лист3
A1: Оборудование | B1: Стоимость | C1: Количество
A2: 3хЗНОЛП-ЭК-10 М1ТА | B2: 55150 | C2: 3
B33: 0.15

Sheet расчет
A1: 0 | B1: оборудование | C1: стоимость | D1: оборудование2 | E1: стоимость3 | F1: оборудование4 | G1: стоимость5 | H1: оборудование6 | I1: стоимость7 | J1: оборудование8 | K1: стоимость9 | L1: оборудование10 | M1: стоимость11 | N1: оборудование12 | O1: стоимость13 | P1: оборудование14 | Q1: стоимость15 | R1: оборудование16 | S1: стоимость17 | T1: оборудование18 | U1: стоимость19 | X1: 1 | Y1: 2 | Z1: 3 | AA1: 4 | AB1: 5 | AC1: 6 | AD1: 7 | AE1: 8 | AF1: 9 | AG1: 10 | AI1: 1 | AJ1: 2 | AK1: 3 | AL1: 4 | AM1: 5 | AN1: 6 | AO1: 7 | AP1: 8 | AQ1: 9 | AR1: 10 | AT1: 1 | AU1: 2 | AV1: 3 | AW1: 4 | AX1: 5 | AY1: 6 | AZ1: 7 | BA1: 8 | BB1: 9 | BC1: 10 | BF1: 211
A2: ='КСО-204'!C7 -> КСО-204 | B2: =IF('КСО-204'!$C$7="КСО-211","",IF('КСО-204'!D17="","",'КСО-204'!D17)) -> РВФЗ-10/1000 | C2: =IFERROR(VLOOKUP(B2,Прайсы!$L$3:$M$20,2,FALSE),1) -> 34320 | D2: =IF('КСО-204'!$C$7="КСО-211","",IF('КСО-204'!E17="","",'КСО-204'!E17)) -> РВФЗ-10/1000 | E2: =IFERROR(VLOOKUP(D2,Прайсы!$L$3:$M$20,2,FALSE),1) -> 34320 | F2: =IF('КСО-204'!$C$7="КСО-211","",IF('КСО-204'!F17="","",'КСО-204'!F17)) -> РВФЗ-10/1000 | G2: =IFERROR(VLOOKUP(F2,Прайсы!$L$3:$M$20,2,FALSE),1) -> 34320 | H2: =IF('КСО-204'!$C$7="КСО-211","",IF('КСО-204'!G17="","",'КСО-204'!G17)) -> РВФЗ-10/1000 | I2: =IFERROR(VLOOKUP(H2,Прайсы!$L$3:$M$20,2,FALSE),1) -> 34320 | J2: =IF('КСО-204'!$C$7="КСО-211","",IF('КСО-204'!H17="","",'КСО-204'!H17)) -> РВФЗ-10/1000 | K2: =IFERROR(VLOOKUP(J2,Прайсы!$L$3:$M$20,2,FALSE),1) -> 34320 | L2: =IF('КСО-204'!$C$7="КСО-211","",IF('КСО-204'!I17="","",'КСО-204'!I17)) -> РВФЗ-10/1000 | M2: =IFERROR(VLOOKUP(L2,Прайсы!$L$3:$M$20,2,FALSE),1) -> 34320 | N2: =IF('КСО-204'!$C$7="КСО-211","",IF('КСО-204'!J17="","",'КСО-204'!J17)) -> РВФЗ-10/1000 | O2: =IFERROR(VLOOKUP(N2,Прайсы!$L$3:$M$20,2,FALSE),1) -> 34320 | P2: =IF('КСО-204'!$C$7="КСО-211","",IF('КСО-204'!K17="","",'КСО-204'!K17)) | Q2: =IFERROR(VLOOKUP(P2,Прайсы!$L$3:$M$20,2,FALSE),1) -> 1 | R2: =IF('КСО-204'!$C$7="КСО-211","",IF('КСО-204'!L17="","",'КСО-204'!L17)) | S2: =IFERROR(VLOOKUP(R2,Прайсы!$L$3:$M$20,2,FALSE),1) -> 1 | T2: =IF('КСО-204'!$C$7="КСО-211","",IF('КСО-204'!M17="","",'КСО-204'!M17)) | U2: =IFERROR(VLOOKUP(T2,Прайсы!$L$3:$M$20,2,FALSE),1) -> 1 | W2: Рвз | X2: =IF('КСО-204'!D17<>"",1,0) -> 1 | Y2: =IF('КСО-204'!E17<>"",1,0) -> 1 | Z2: =IF('КСО-204'!F17<>"",1,0) -> 1 | AA2: =IF('КСО-204'!G17<>"",1,0) -> 1 | AB2: =IF('КСО-204'!H17<>"",1,0) -> 1 | AC2: =IF('КСО-204'!I17<>"",1,0) -> 1 | AD2: =IF('КСО-204'!J17<>"",1,0) -> 1 | AE2: =IF('КСО-204'!K17<>"",1,0) -> 0 | ... AG2: =IF('КСО-204'!M17<>"",1,0) -> 0 | AI2: =REPLACE(B2,1,7,"") -> /1000 | AJ2: =REPLACE(D2,1,7,"") -> /1000 | AK2: =REPLACE(F2,1,7,"") -> /1000 | AL2: =REPLACE(H2,1,7,"") -> /1000 | AM2: =REPLACE(J2,1,7,"") -> /1000 | AN2: =REPLACE(L2,1,7,"") -> /1000 | AO2: =REPLACE(N2,1,7,"") -> /1000 | AP2: =REPLACE(P2,1,7,"") | AQ2: =REPLACE(R2,1,7,"") | AR2: =REPLACE(T2,1,7,"") | AT2: =VLOOKUP(Таблица13[[#This Row],[оборудование]],Таблица_Регистрация_2012_год.accdb[[РВЗ]:[Дата]],3,FALSE) -> 45330 | AU2: =VLOOKUP(Таблица13[[#This Row],[оборудование2]],Таблица_Регистрация_2012_год.accdb[[РВЗ]:[Дата]],3,FALSE) -> 45330 | AV2: =VLOOKUP(Таблица13[[#This Row],[оборудование4]],Таблица_Регистрация_2012_год.accdb[[РВЗ]:[Дата]],3,FALSE) -> 45330 | AW2: =VLOOKUP(Таблица13[[#This Row],[оборудование6]],Таблица_Регистрация_2012_год.accdb[[РВЗ]:[Дата]],3,FALSE) -> 45330 | AX2: =VLOOKUP(Таблица13[[#This Row],[оборудование8]],Таблица_Регистрация_2012_год.accdb[[РВЗ]:[Дата]],3,FALSE) -> 45330 | AY2: =VLOOKUP(Таблица13[[#This Row],[оборудование10]],Таблица_Регистрация_2012_год.accdb[[РВЗ]:[Дата]],3,FALSE) -> 45330 | AZ2: =VLOOKUP(Таблица13[[#This Row],[оборудование12]],Таблица_Регистрация_2012_год.accdb[[РВЗ]:[Дата]],3,FALSE) -> 45330 | BA2: =VLOOKUP(Таблица13[[#This Row],[оборудование14]],Таблица_Регистрация_2012_год.accdb[[РВЗ]:[Дата]],3,FALSE) -> #N/A | BB2: =VLOOKUP(Таблица13[[#This Row],[оборудование16]],Таблица_Регистрация_2012_год.accdb[[РВЗ]:[Дата]],3,FALSE) -> #N/A | BC2: =VLOOKUP(Таблица13[[#This Row],[оборудование18]],Таблица_Регистрация_2012_год.accdb[[РВЗ]:[Дата]],3,FALSE) -> #N/A | BE2: 630/1000 | BF2: 630/1000 | BG2: 1600
B3: =IF('КСО-204'!D18="","",'КСО-204'!D18) -> VM12-10-20/1000 | C3: =IFERROR(VLOOKUP(B3,Прайсы!$CB$3:$CC$50,2,FALSE),0) -> 117020 | D3: =IF('КСО-204'!E18="","",'КСО-204'!E18) -> VM12-10-20/1000 | E3: =IFERROR(VLOOKUP(D3,Прайсы!$CB$3:$CC$50,2,FALSE),0) -> 117020 | F3: =IF('КСО-204'!F18="","",'КСО-204'!F18) -> VM12-10-20/1000 | G3: =IFERROR(VLOOKUP(F3,Прайсы!$CB$3:$CC$50,2,FALSE),0) -> 117020 | H3: =IF('КСО-204'!G18="","",'КСО-204'!G18) | I3: =IFERROR(VLOOKUP(H3,Прайсы!$CB$3:$CC$50,2,FALSE),0) -> 0 | J3: =IF('КСО-204'!H18="","",'КСО-204'!H18) | K3: =IFERROR(VLOOKUP(J3,Прайсы!$CB$3:$CC$50,2,FALSE),0) -> 0 | L3: =IF('КСО-204'!I18="","",'КСО-204'!I18) -> VM12-10-20/1000 | M3: =IFERROR(VLOOKUP(L3,Прайсы!$CB$3:$CC$50,2,FALSE),0) -> 117020 | N3: =IF('КСО-204'!J18="","",'КСО-204'!J18) | O3: =IFERROR(VLOOKUP(N3,Прайсы!$CB$3:$CC$50,2,FALSE),0) -> 0 | P3: =IF('КСО-204'!K18="","",'КСО-204'!K18) | Q3: =IFERROR(VLOOKUP(P3,Прайсы!$CB$3:$CC$50,2,FALSE),0) -> 0 | R3: =IF('КСО-204'!L18="","",'КСО-204'!L18) | S3: =IFERROR(VLOOKUP(R3,Прайсы!$CB$3:$CC$50,2,FALSE),0) -> 0 | T3: =IF('КСО-204'!M18="","",'КСО-204'!M18) | U3: =IFERROR(VLOOKUP(T3,Прайсы!$CB$3:$CC$50,2,FALSE),0) -> 0 | W3: вв | X3: =IF(B3<>"",1,0) -> 1 | Y3: =IF(D3<>"",1,0) -> 1 | Z3: =IF(F3<>"",1,0) -> 1 | AA3: =IF(H3<>"",1,0) -> 0 | AB3: =IF(J3<>"",1,0) -> 0 | AC3: =IF(L3<>"",1,0) -> 1 | AD3: =IF(N3<>"",1,0) -> 0 | AE3: =IF(P3<>"",1,0) -> 0 | AF3: =IF(R3<>"",1,0) -> 0 | AG3: =IF(T3<>"",1,0) -> 0 | AT3: =VLOOKUP(Таблица13[[#This Row],[оборудование]],Таблица_Регистрация_2012_год.accdb_10[[Выкл]:[дата]],3,FALSE) -> 45300 | AU3: =VLOOKUP(Таблица13[[#This Row],[оборудование2]],Таблица_Регистрация_2012_год.accdb_10[[Выкл]:[дата]],3,FALSE) -> 45300 | AV3: =VLOOKUP(Таблица13[[#This Row],[оборудование4]],Таблица_Регистрация_2012_год.accdb_10[[Выкл]:[дата]],3,FALSE) -> 45300 | AW3: =VLOOKUP(Таблица13[[#This Row],[оборудование6]],Таблица_Регистрация_2012_год.accdb_10[[Выкл]:[дата]],3,FALSE) -> #N/A | AX3: =VLOOKUP(Таблица13[[#This Row],[оборудование8]],Таблица_Регистрация_2012_год.accdb_10[[Выкл]:[дата]],3,FALSE) -> #N/A | AY3: =VLOOKUP(Таблица13[[#This Row],[оборудование10]],Таблица_Регистрация_2012_год.accdb_10[[Выкл]:[дата]],3,FALSE) -> 45300 | AZ3: =VLOOKUP(Таблица13[[#This Row],[оборудование12]],Таблица_Регистрация_2012_год.accdb_10[[Выкл]:[дата]],3,FALSE) -> #N/A | BA3: =VLOOKUP(Таблица13[[#This Row],[оборудование14]],Таблица_Регистрация_2012_год.accdb_10[[Выкл]:[дата]],3,FALSE) -> #N/A | BB3: =VLOOKUP(Таблица13[[#This Row],[оборудование16]],Таблица_Регистрация_2012_год.accdb_10[[Выкл]:[дата]],3,FALSE) -> #N/A | BC3: =VLOOKUP(Таблица13[[#This Row],[оборудование18]],Таблица_Регистрация_2012_год.accdb_10[[Выкл]:[дата]],3,FALSE) -> #N/A | BE3: 1 | BF3: 1 | BG3: 1
B4: =IF('КСО-204'!D19="","",'КСО-204'!D19) -> CVM 1.2 ВЕАШ468389.001-01 | C4: =IFERROR(VLOOKUP(B4,Прайсы!$BC$3:$BD$7,2,FALSE),0) -> 29620 | D4: =IF('КСО-204'!E19="","",'КСО-204'!E19) -> CVM 1.2 ВЕАШ468389.001-01 | E4: =IFERROR(VLOOKUP(D4,Прайсы!$BC$3:$BD$7,2,FALSE),0) -> 29620 | F4: =IF('КСО-204'!F19="","",'КСО-204'!F19) -> CVM 1.2 ВЕАШ468389.001-01 | G4: =IFERROR(VLOOKUP(F4,Прайсы!$BC$3:$BD$7,2,FALSE),0) -> 29620 | H4: =IF('КСО-204'!G19="","",'КСО-204'!G19) | I4: =IFERROR(VLOOKUP(H4,Прайсы!$BC$3:$BD$7,2,FALSE),0) -> 0 | J4: =IF('КСО-204'!H19="","",'КСО-204'!H19) | K4: =IFERROR(VLOOKUP(J4,Прайсы!$BC$3:$BD$7,2,FALSE),0) -> 0 | L4: =IF('КСО-204'!I19="","",'КСО-204'!I19) -> CVM 1.2 ВЕАШ468389.001-01 | M4: =IFERROR(VLOOKUP(L4,Прайсы!$BC$3:$BD$7,2,FALSE),0) -> 29620 | N4: =IF('КСО-204'!J19="","",'КСО-204'!J19) | O4: =IFERROR(VLOOKUP(N4,Прайсы!$BC$3:$BD$7,2,FALSE),0) -> 0 | P4: =IF('КСО-204'!K19="","",'КСО-204'!K19) | Q4: =IFERROR(VLOOKUP(P4,Прайсы!$BC$3:$BD$7,2,FALSE),0) -> 0 | R4: =IF('КСО-204'!L19="","",'КСО-204'!L19) | S4: =IFERROR(VLOOKUP(R4,Прайсы!$BC$3:$BD$7,2,FALSE),0) -> 0 | T4: =IF('КСО-204'!M19="","",'КСО-204'!M19) | U4: =IFERROR(VLOOKUP(T4,Прайсы!$BC$3:$BD$7,2,FALSE),0) -> 0 | AT4: =VLOOKUP(Таблица13[[#This Row],[оборудование]],Таблица_Регистрация_2012_год.accdb_6[[БУ]:[дата]],3,FALSE) -> 45300 | AU4: =VLOOKUP(Таблица13[[#This Row],[оборудование2]],Таблица_Регистрация_2012_год.accdb_6[[БУ]:[дата]],3,FALSE) -> 45300 | AV4: =VLOOKUP(Таблица13[[#This Row],[оборудование4]],Таблица_Регистрация_2012_год.accdb_6[[БУ]:[дата]],3,FALSE) -> 45300 | AW4: =VLOOKUP(Таблица13[[#This Row],[оборудование6]],Таблица_Регистрация_2012_год.accdb_6[[БУ]:[дата]],3,FALSE) -> #N/A | AX4: =VLOOKUP(Таблица13[[#This Row],[оборудование8]],Таблица_Регистрация_2012_год.accdb_6[[БУ]:[дата]],3,FALSE) -> #N/A | AY4: =VLOOKUP(Таблица13[[#This Row],[оборудование10]],Таблица_Регистрация_2012_год.accdb_6[[БУ]:[дата]],3,FALSE) -> 45300 | AZ4: =VLOOKUP(Таблица13[[#This Row],[оборудование12]],Таблица_Регистрация_2012_год.accdb_6[[БУ]:[дата]],3,FALSE) -> #N/A | BA4: =VLOOKUP(Таблица13[[#This Row],[оборудование14]],Таблица_Регистрация_2012_год.accdb_6[[БУ]:[дата]],3,FALSE) -> #N/A | BB4: =VLOOKUP(Таблица13[[#This Row],[оборудование16]],Таблица_Регистрация_2012_год.accdb_6[[БУ]:[дата]],3,FALSE) -> #N/A | BC4: =VLOOKUP(Таблица13[[#This Row],[оборудование18]],Таблица_Регистрация_2012_год.accdb_6[[БУ]:[дата]],3,FALSE) -> #N/A | BE4: 8 | BF4: 8 | BG4: 8
B5: =IF('КСО-204'!D20="","",'КСО-204'!D20) -> АГАТ 200. А | C5: =IFERROR(VLOOKUP(B5,Прайсы!$AW$3:$AX$108,2,FALSE),0) -> 70833 | D5: =IF('КСО-204'!E20="","",'КСО-204'!E20) -> АГАТ 200. А | E5: =IFERROR(VLOOKUP(D5,Прайсы!$AW$3:$AX$108,2,FALSE),0) -> 70833 | F5: =IF('КСО-204'!F20="","",'КСО-204'!F20) -> АГАТ 200. АВ | G5: =IFERROR(VLOOKUP(F5,Прайсы!$AW$3:$AX$108,2,FALSE),0) -> 79167 | H5: =IF('КСО-204'!G20="","",'КСО-204'!G20) | I5: =IFERROR(VLOOKUP(H5,Прайсы!$AW$3:$AX$108,2,FALSE),0) -> 0 | J5: =IF('КСО-204'!H20="","",'КСО-204'!H20) -> АГАТ 200. В | K5: =IFERROR(VLOOKUP(J5,Прайсы!$AW$3:$AX$108,2,FALSE),0) -> 70833 | L5: =IF('КСО-204'!I20="","",'КСО-204'!I20) -> АГАТ 200. АВ | M5: =IFERROR(VLOOKUP(L5,Прайсы!$AW$3:$AX$108,2,FALSE),0) -> 79167 | N5: =IF('КСО-204'!J20="","",'КСО-204'!J20) | O5: =IFERROR(VLOOKUP(N5,Прайсы!$AW$3:$AX$108,2,FALSE),0) -> 0 | P5: =IF('КСО-204'!K20="","",'КСО-204'!K20) | Q5: =IFERROR(VLOOKUP(P5,Прайсы!$AW$3:$AX$108,2,FALSE),0) -> 0 | R5: =IF('КСО-204'!L20="","",'КСО-204'!L20) | S5: =IFERROR(VLOOKUP(R5,Прайсы!$AW$3:$AX$108,2,FALSE),0) -> 0 | T5: =IF('КСО-204'!M20="","",'КСО-204'!M20) | U5: =IFERROR(VLOOKUP(T5,Прайсы!$AW$3:$AX$108,2,FALSE),0) -> 0 | AT5: =VLOOKUP(Таблица13[[#This Row],[оборудование]],Таблица_Регистрация_2012_год.accdb_5[[МПЗ]:[Дата]],3,FALSE) -> 45677 | AU5: =VLOOKUP(Таблица13[[#This Row],[оборудование2]],Таблица_Регистрация_2012_год.accdb_5[[МПЗ]:[Дата]],3,FALSE) -> 45677 | AV5: =VLOOKUP(Таблица13[[#This Row],[оборудование4]],Таблица_Регистрация_2012_год.accdb_5[[МПЗ]:[Дата]],3,FALSE) -> 45677 | AW5: =VLOOKUP(Таблица13[[#This Row],[оборудование6]],Таблица_Регистрация_2012_год.accdb_5[[МПЗ]:[Дата]],3,FALSE) -> #N/A | AX5: =VLOOKUP(Таблица13[[#This Row],[оборудование8]],Таблица_Регистрация_2012_год.accdb_5[[МПЗ]:[Дата]],3,FALSE) -> 45677 | AY5: =VLOOKUP(Таблица13[[#This Row],[оборудование10]],Таблица_Регистрация_2012_год.accdb_5[[МПЗ]:[Дата]],3,FALSE) -> 45677 | AZ5: =VLOOKUP(Таблица13[[#This Row],[оборудование12]],Таблица_Регистрация_2012_год.accdb_5[[МПЗ]:[Дата]],3,FALSE) -> #N/A | BA5: =VLOOKUP(Таблица13[[#This Row],[оборудование14]],Таблица_Регистрация_2012_год.accdb_5[[МПЗ]:[Дата]],3,FALSE) -> #N/A | BB5: =VLOOKUP(Таблица13[[#This Row],[оборудование16]],Таблица_Регистрация_2012_год.accdb_5[[МПЗ]:[Дата]],3,FALSE) -> #N/A | BC5: =VLOOKUP(Таблица13[[#This Row],[оборудование18]],Таблица_Регистрация_2012_год.accdb_5[[МПЗ]:[Дата]],3,FALSE) -> #N/A | BE5: =4+5 -> 9 | BF5: =4+5 -> 9 | BG5: =4*2+5*2 -> 18 | BH5: ="+сборная 5м" -> +сборная 5м
B6: =IF('КСО-204'!D21="","",'КСО-204'!D21) -> 3 | C6: =IF(AND(B6=1,B3=""),"ОШИБКА",IF(B6=1,0,IF(B6=2,C7,2*C7))) -> 46080 | D6: =IF('КСО-204'!E21="","",'КСО-204'!E21) -> 3 | E6: =IF(AND(D6=1,D3=""),"ОШИБКА",IF(D6=1,0,IF(D6=2,E7,2*E7))) -> 46080 | F6: =IF('КСО-204'!F21="","",'КСО-204'!F21) -> 3 | G6: =IF(AND(F6=1,F3=""),"ОШИБКА",IF(F6=1,0,IF(F6=2,G7,2*G7))) -> 44880 | H6: =IF('КСО-204'!G21="","",'КСО-204'!G21) | I6: =IF(AND(H6=1,H3=""),"ОШИБКА",IF(H6=1,0,IF(H6=2,I7,2*I7))) -> 0 | J6: =IF('КСО-204'!H21="","",'КСО-204'!H21) | K6: =IF(AND(J6=1,J3=""),"ОШИБКА",IF(J6=1,0,IF(J6=2,K7,2*K7))) -> 0 | L6: =IF('КСО-204'!I21="","",'КСО-204'!I21) -> 3 | M6: =IF(AND(L6=1,L3=""),"ОШИБКА",IF(L6=1,0,IF(L6=2,M7,2*M7))) -> 46080 | N6: =IF('КСО-204'!J21="","",'КСО-204'!J21) | O6: =IF(AND(N6=1,N3=""),"ОШИБКА",IF(N6=1,0,IF(N6=2,O7,2*O7))) -> 0 | P6: =IF('КСО-204'!K21="","",'КСО-204'!K21) | Q6: =IF(AND(P6=1,P3=""),"ОШИБКА",IF(P6=1,0,IF(P6=2,Q7,2*Q7))) -> 0 | R6: =IF('КСО-204'!L21="","",'КСО-204'!L21) | S6: =IF(AND(R6=1,R3=""),"ОШИБКА",IF(R6=1,0,IF(R6=2,S7,2*S7))) -> 0 | T6: =IF('КСО-204'!M21="","",'КСО-204'!M21) | U6: =IF(AND(T6=1,T3=""),"ОШИБКА",IF(T6=1,0,IF(T6=2,U7,2*U7))) -> 0 | W6: ТТ | X6: =IF(B6="",0,B6) -> 3 | Y6: =IF(D6="",0,D6) -> 3 | Z6: =IF(F6="",0,F6) -> 3 | AA6: =IF(H6="",0,H6) -> 0 | AB6: =IF(J6="",0,J6) -> 0 | AC6: =IF(L6="",0,L6) -> 3 | AD6: =IF(N6="",0,N6) -> 0 | AE6: =IF(P6="",0,P6) -> 0 | AF6: =IF(R6="",0,R6) -> 0 | AG6: =IF(T6="",0,T6) -> 0 | BE6: AL | BF6: Cu | BG6: Cu
B7: =IF('КСО-204'!D22="","",'КСО-204'!D22) -> ТПЛ-10 200/5 0,5S/10P | C7: =IFERROR(VLOOKUP(B7,Прайсы!$B$3:$C$122,2,FALSE),0) -> 23040 | D7: =IF('КСО-204'!E22="","",'КСО-204'!E22) -> ТПЛ-10 600/5 0,5S/10P | E7: =IFERROR(VLOOKUP(D7,Прайсы!$B$3:$C$122,2,FALSE),0) -> 23040 | F7: =IF('КСО-204'!F22="","",'КСО-204'!F22) -> ТПЛ-10 1000/5 0,5S/10P | G7: =IFERROR(VLOOKUP(F7,Прайсы!$B$3:$C$122,2,FALSE),0) -> 22440 | H7: =IF('КСО-204'!G22="","",'КСО-204'!G22) | I7: =IFERROR(VLOOKUP(H7,Прайсы!$B$3:$C$122,2,FALSE),0) -> 0 | J7: =IF('КСО-204'!H22="","",'КСО-204'!H22) | K7: =IFERROR(VLOOKUP(J7,Прайсы!$B$3:$C$122,2,FALSE),0) -> 0 | L7: =IF('КСО-204'!I22="","",'КСО-204'!I22) -> ТПЛ-10 800/5 0,5S/10P | M7: =IFERROR(VLOOKUP(L7,Прайсы!$B$3:$C$122,2,FALSE),0) -> 23040 | N7: =IF('КСО-204'!J22="","",'КСО-204'!J22) | O7: =IFERROR(VLOOKUP(N7,Прайсы!$B$3:$C$122,2,FALSE),0) -> 0 | P7: =IF('КСО-204'!K22="","",'КСО-204'!K22) | Q7: =IFERROR(VLOOKUP(P7,Прайсы!$B$3:$C$122,2,FALSE),0) -> 0 | R7: =IF('КСО-204'!L22="","",'КСО-204'!L22) | S7: =IFERROR(VLOOKUP(R7,Прайсы!$B$3:$C$122,2,FALSE),0) -> 0 | T7: =IF('КСО-204'!M22="","",'КСО-204'!M22) | U7: =IFERROR(VLOOKUP(T7,Прайсы!$B$3:$C$122,2,FALSE),0) -> 0 | AT7: =VLOOKUP(Таблица13[[#This Row],[оборудование]],Таблица_Регистрация_2012_год.accdb_1[[ТТ]:[Дата]],3,FALSE) -> 45614 | AU7: =VLOOKUP(Таблица13[[#This Row],[оборудование2]],Таблица_Регистрация_2012_год.accdb_1[[ТТ]:[Дата]],3,FALSE) -> 45614 | AV7: =VLOOKUP(Таблица13[[#This Row],[оборудование4]],Таблица_Регистрация_2012_год.accdb_1[[ТТ]:[Дата]],3,FALSE) -> 45614 | AW7: =VLOOKUP(Таблица13[[#This Row],[оборудование6]],Таблица_Регистрация_2012_год.accdb_1[[ТТ]:[Дата]],3,FALSE) -> #N/A | AX7: =VLOOKUP(Таблица13[[#This Row],[оборудование8]],Таблица_Регистрация_2012_год.accdb_1[[ТТ]:[Дата]],3,FALSE) -> #N/A | AY7: =VLOOKUP(Таблица13[[#This Row],[оборудование10]],Таблица_Регистрация_2012_год.accdb_1[[ТТ]:[Дата]],3,FALSE) -> 45614 | AZ7: =VLOOKUP(Таблица13[[#This Row],[оборудование12]],Таблица_Регистрация_2012_год.accdb_1[[ТТ]:[Дата]],3,FALSE) -> #N/A | BA7: =VLOOKUP(Таблица13[[#This Row],[оборудование14]],Таблица_Регистрация_2012_год.accdb_1[[ТТ]:[Дата]],3,FALSE) -> #N/A | BB7: =VLOOKUP(Таблица13[[#This Row],[оборудование16]],Таблица_Регистрация_2012_год.accdb_1[[ТТ]:[Дата]],3,FALSE) -> #N/A | BC7: =VLOOKUP(Таблица13[[#This Row],[оборудование18]],Таблица_Регистрация_2012_год.accdb_1[[ТТ]:[Дата]],3,FALSE) -> #N/A | BE7: =BE3*Прайсы!EU3 -> 188 | BF7: =BF3*Прайсы!EO3 -> 1319 | BG7: =BG3*Прайсы!EO3 -> 1319
B8: =IF('КСО-204'!D23="","",'КСО-204'!D23) -> РВЗ-10/1000 | C8: =IFERROR(VLOOKUP(B8,Прайсы!$L$3:$M$20,2,FALSE),0) -> 22568 | D8: =IF('КСО-204'!E23="","",'КСО-204'!E23) -> РВЗ-10/1000 | E8: =IFERROR(VLOOKUP(D8,Прайсы!$L$3:$M$20,2,FALSE),0) -> 22568 | F8: =IF('КСО-204'!F23="","",'КСО-204'!F23) -> РВЗ-10/1000 | G8: =IFERROR(VLOOKUP(F8,Прайсы!$L$3:$M$20,2,FALSE),0) -> 22568 | H8: =IF('КСО-204'!G23="","",'КСО-204'!G23) | I8: =IFERROR(VLOOKUP(H8,Прайсы!$L$3:$M$20,2,FALSE),0) -> 0 | J8: =IF('КСО-204'!H23="","",'КСО-204'!H23) -> ЗР-10 | K8: =IFERROR(VLOOKUP(J8,Прайсы!$L$3:$M$20,2,FALSE),0) -> 11519 | L8: =IF('КСО-204'!I23="","",'КСО-204'!I23) | M8: =IFERROR(VLOOKUP(L8,Прайсы!$L$3:$M$20,2,FALSE),0) -> 0 | N8: =IF('КСО-204'!J23="","",'КСО-204'!J23) | O8: =IFERROR(VLOOKUP(N8,Прайсы!$L$3:$M$20,2,FALSE),0) -> 0 | P8: =IF('КСО-204'!K23="","",'КСО-204'!K23) | Q8: =IFERROR(VLOOKUP(P8,Прайсы!$L$3:$M$20,2,FALSE),0) -> 0 | R8: =IF('КСО-204'!L23="","",'КСО-204'!L23) | S8: =IFERROR(VLOOKUP(R8,Прайсы!$L$3:$M$20,2,FALSE),0) -> 0 | T8: =IF('КСО-204'!M23="","",'КСО-204'!M23) | U8: =IFERROR(VLOOKUP(T8,Прайсы!$L$3:$M$20,2,FALSE),0) -> 0 | W8: рвз | X8: =IF(B8<>"",1,0) -> 1 | Y8: =IF(D8<>"",1,0) -> 1 | Z8: =IF(F8<>"",1,0) -> 1 | AA8: =IF(H8<>"",1,0) -> 0 | AB8: =IF(J8<>"",1,0) -> 1 | AC8: =IF(L8<>"",1,0) -> 0 | AD8: =IF(N8<>"",1,0) -> 0 | AE8: =IF(P8<>"",1,0) -> 0 | AF8: =IF(R8<>"",1,0) -> 0 | AG8: =IF(T8<>"",1,0) -> 0 | AT8: =VLOOKUP(Таблица13[[#This Row],[оборудование]],Таблица_Регистрация_2012_год.accdb[[РВЗ]:[Дата]],3,FALSE) -> 45680 | AU8: =VLOOKUP(Таблица13[[#This Row],[оборудование2]],Таблица_Регистрация_2012_год.accdb[[РВЗ]:[Дата]],3,FALSE) -> 45680 | AV8: =VLOOKUP(Таблица13[[#This Row],[оборудование4]],Таблица_Регистрация_2012_год.accdb[[РВЗ]:[Дата]],3,FALSE) -> 45680 | AW8: =VLOOKUP(Таблица13[[#This Row],[оборудование6]],Таблица_Регистрация_2012_год.accdb[[РВЗ]:[Дата]],3,FALSE) -> #N/A | AX8: =VLOOKUP(Таблица13[[#This Row],[оборудование8]],Таблица_Регистрация_2012_год.accdb[[РВЗ]:[Дата]],3,FALSE) -> 45680 | AY8: =VLOOKUP(Таблица13[[#This Row],[оборудование10]],Таблица_Регистрация_2012_год.accdb[[РВЗ]:[Дата]],3,FALSE) -> #N/A | AZ8: =VLOOKUP(Таблица13[[#This Row],[оборудование12]],Таблица_Регистрация_2012_год.accdb[[РВЗ]:[Дата]],3,FALSE) -> #N/A | BA8: =VLOOKUP(Таблица13[[#This Row],[оборудование14]],Таблица_Регистрация_2012_год.accdb[[РВЗ]:[Дата]],3,FALSE) -> #N/A | BB8: =VLOOKUP(Таблица13[[#This Row],[оборудование16]],Таблица_Регистрация_2012_год.accdb[[РВЗ]:[Дата]],3,FALSE) -> #N/A | BC8: =VLOOKUP(Таблица13[[#This Row],[оборудование18]],Таблица_Регистрация_2012_год.accdb[[РВЗ]:[Дата]],3,FALSE) -> #N/A | BE8: =BE4*Прайсы!EU4 -> 2384 | BF8: =BF4*Прайсы!EO4 -> 17584 | BG8: =BG4*Прайсы!EO4 -> 17584
